Workbook
Name Family: [1]Coefficients!$AI$9:$AI$10
Name FamSelect: [1]Coefficients!$AJ$8
Name Princeton: [1]Coefficients!$AI$13:$AI$16
Name Sex: [1]Coefficients!$AI$29:$AI$31
Name UN: [1]Coefficients!$AI$17:$AI$21
Name Variant: [1]Coefficients!$AI$24:$AI$26

Sheet DM_2019
B2: Hombres, 2019
B3: Age x | C3: n | D3: nDx | E3: nDxi | I3: nqx | K3: e0 | M3: nqx_i | O3: ndx_i | Q3: L | R3: T | S3: e0_i | T3: diff
B4: 0 | C4: 1 | D4: ='Defunciones generales'!D21 -> 472 | E4: =Homicidios!N26 -> 0 | F4: =(D4-E4)/D4 -> 1 | G4: =tabla_mortalidad_hombre_2019!G2 -> 100000 | H4: =tabla_mortalidad_hombre_2019!F2 -> 0.98195108 | I4: =1-H4 -> 0.018048919 | J4: =tabla_mortalidad_hombre_2019!D2 -> 0.094248405 | K4: =tabla_mortalidad_hombre_2019!K2 -> 68.046242 | L4: =H4^F4 -> 0.98195108 | M4: =1-L4 -> 0.018048919 | N4: 100000 | O4: =N4*M4 -> 1804.8919 | P4: =C4+(F4*(I4/M4)*(J4-C4)) -> 0.094248405 | Q4: =(C4*N5)+(P4*O4) -> 98365.216 | R4: =R5+Q4 -> 7108901.3 | S4: =R4/N4 -> 71.089013 | T4: =S4-K4 -> 3.0427709
B5: 1 | C5: 4 | D5: ='Defunciones generales'!D22 -> 90 | E5: =Homicidios!N27 -> 2.0019666 | F5: =(D5-E5)/D5 -> 0.97775593 | G5: =tabla_mortalidad_hombre_2019!G3 -> 98195.108 | H5: =tabla_mortalidad_hombre_2019!F3 -> 0.99709267 | I5: =1-H5 -> 0.0029073262 | J5: =tabla_mortalidad_hombre_2019!D3 -> 1.5993295 | K5: =tabla_mortalidad_hombre_2019!K3 -> 68.295245 | L5: =H5^F5 -> 0.99715725 | M5: =1-L5 -> 0.0028427474 | N5: =N4*L4 -> 98195.108 | O5: =N5*M5 -> 279.14389 | P5: =C5+(F5*(I5/M5)*(J5-C5)) -> 1.5994072 | Q5: =(C5*N6)+(P5*O5) -> 392110.32 | R5: =R6+Q5 -> 7010536.1 | S5: =R5/N5 -> 71.393944 | T5: =S5-K5 -> 3.0986991 | V5: Número de años que se espera que viva un hombre de 0 años hasta llegar a los 85 años.
B6: 5 | C6: 5 | D6: ='Defunciones generales'!D23 -> 44 | E6: =Homicidios!N28 -> 2.0019666 | F6: =(D6-E6)/D6 -> 0.95450076 | G6: =tabla_mortalidad_hombre_2019!G4 -> 97909.623 | H6: =tabla_mortalidad_hombre_2019!F4 -> 0.99864719 | I6: =1-H6 -> 0.0013528143 | J6: =tabla_mortalidad_hombre_2019!D4 -> 2.5 | K6: =tabla_mortalidad_hombre_2019!K4 -> 64.489717 | L6: =H6^F6 -> 0.9987087 | M6: =1-L6 -> 0.0012913021 | N6: =N5*L5 -> 97915.964 | O6: =N6*M6 -> 126.43909 | P6: =C6+(F6*(I6/M6)*(J6-C6)) -> 2.500077 | Q6: =(C6*N7)+(P6*O6) -> 489263.73 | R6: =R7+Q6 -> 6618425.8 | S6: =R6/N6 -> 67.592918 | T6: =S6-K6 -> 3.1032008
B7: 10 | C7: 5 | D7: ='Defunciones generales'!D24 -> 71 | E7: =Homicidios!N29 -> 6.0058997 | F7: =(D7-E7)/D7 -> 0.91540986 | G7: =tabla_mortalidad_hombre_2019!G5 -> 97777.169 | H7: =tabla_mortalidad_hombre_2019!F5 -> 0.99791349 | I7: =1-H7 -> 0.002086506 | J7: =tabla_mortalidad_hombre_2019!D5 -> 2.5 | K7: =tabla_mortalidad_hombre_2019!K5 -> 59.573692 | L7: =H7^F7 -> 0.99808982 | M7: =1-L7 -> 0.0019101768 | N7: =N6*L6 -> 97789.525 | O7: =N7*M7 -> 186.79529 | P7: =(((-5/24)*O6)+((2.5)*O7)+((5/24)*O8))/O7 -> 3.0042498 | Q7: =(C7*N8)+(P7*O7) -> 488574.83 | R7: =R8+Q7 -> 6129162 | S7: =R7/N7 -> 62.677081 | T7: =S7-K7 -> 3.1033898
B8: 15 | C8: 5 | D8: ='Defunciones generales'!D25 -> 366 | E8: =Homicidios!N30 -> 168.16519 | F8: =(D8-E8)/D8 -> 0.54053226 | G8: =tabla_mortalidad_hombre_2019!G6 -> 97573.157 | H8: =tabla_mortalidad_hombre_2019!F6 -> 0.98906125 | I8: =1-H8 -> 0.010938748 | J8: =tabla_mortalidad_hombre_2019!D6 -> 2.5 | K8: =tabla_mortalidad_hombre_2019!K6 -> 54.693025 | L8: =H8^F8 -> 0.99407232 | M8: =1-L8 -> 0.0059276845 | N8: =N7*L7 -> 97602.73 | O8: =N8*M8 -> 578.55819 | P8: =(((-5/24)*O7)+((2.5)*O8)+((5/24)*O9))/O8 -> 2.8122884 | Q8: =(C8*N9)+(P8*O8) -> 486747.93 | R8: =R9+Q8 -> 5640587.2 | S8: =R8/N8 -> 57.791285 | T8: =S8-K8 -> 3.09826 | V8: Sin COVID | W8: Con COVID
B9: 20 | C9: 5 | D9: ='Defunciones generales'!D26 -> 711 | E9: =Homicidios!N31 -> 368.36185 | F9: =(D9-E9)/D9 -> 0.4819102 | G9: =tabla_mortalidad_hombre_2019!G7 -> 96505.828 | H9: =tabla_mortalidad_hombre_2019!F7 -> 0.97758854 | I9: =1-H9 -> 0.022411462 | J9: =tabla_mortalidad_hombre_2019!D7 -> 2.5 | K9: =tabla_mortalidad_hombre_2019!K7 -> 50.270266 | L9: =H9^F9 -> 0.98913626 | M9: =1-L9 -> 0.010863735 | N9: =N8*L8 -> 97024.172 | O9: =N9*M9 -> 1054.0449 | P9: =(((-5/24)*O8)+((2.5)*O9)+((5/24)*O10))/O9 -> 2.6281247 | Q9: =(C9*N10)+(P9*O9) -> 482620.79 | R9: =R10+Q9 -> 5153839.3 | S9: =R9/N9 -> 53.119127 | T9: =S9-K9 -> 2.8488609 | V9: =([2]TV!M53-[2]TV!M71)/[2]TV!J53 -> 66.401396 | W9: =(R4-R22)/N4 -> 69.379239
B10: 25 | C10: 5 | D10: ='Defunciones generales'!D27 -> 719 | E10: =Homicidios!N32 -> 341.3353 | F10: =(D10-E10)/D10 -> 0.52526384 | G10: =tabla_mortalidad_hombre_2019!G8 -> 94342.992 | H10: =tabla_mortalidad_hombre_2019!F8 -> 0.97580414 | I10: =1-H10 -> 0.02419586 | J10: =tabla_mortalidad_hombre_2019!D8 -> 2.5 | K10: =tabla_mortalidad_hombre_2019!K8 -> 46.365411 | L10: =H10^F10 -> 0.98721691 | M10: =1-L10 -> 0.012783085 | N10: =N9*L9 -> 95970.127 | O10: =N10*M10 -> 1226.7943 | P10: =(((-5/24)*O9)+((2.5)*O10)+((5/24)*O11))/O10 -> 2.5586024 | Q10: =(C10*N11)+(P10*O10) -> 476855.54 | R10: =R11+Q10 -> 4671218.5 | S10: =R10/N10 -> 48.673672 | T10: =S10-K10 -> 2.3082609 | V10: Diff | W10: =W9-V9 -> 2.9778426
B11: 30 | C11: 5 | D11: ='Defunciones generales'!D28 -> 717 | E11: =Homicidios!N33 -> 314.30875 | F11: =(D11-E11)/D11 -> 0.56163354 | G11: =tabla_mortalidad_hombre_2019!G9 -> 92060.282 | H11: =tabla_mortalidad_hombre_2019!F9 -> 0.97385768 | I11: =1-H11 -> 0.026142319 | J11: =tabla_mortalidad_hombre_2019!D9 -> 2.5 | K11: =tabla_mortalidad_hombre_2019!K9 -> 42.45309 | L11: =H11^F11 -> 0.9852324 | M11: =1-L11 -> 0.014767604 | N11: =N10*L10 -> 94743.332 | O11: =N11*M11 -> 1399.132 | P11: =(((-5/24)*O10)+((2.5)*O11)+((5/24)*O12))/O11 -> 2.5549451 | Q11: =(C11*N12)+(P11*O11) -> 470295.71 | R11: =R12+Q11 -> 4194362.9 | S11: =R11/N11 -> 44.270798 | T11: =S11-K11 -> 1.8177082
B12: 35 | C12: 5 | D12: ='Defunciones generales'!D29 -> 707 | E12: =Homicidios!N34 -> 255.25074 | F12: =(D12-E12)/D12 -> 0.63896643 | G12: =tabla_mortalidad_hombre_2019!G10 -> 89653.613 | H12: =tabla_mortalidad_hombre_2019!F10 -> 0.97337411 | I12: =1-H12 -> 0.026625893 | J12: =tabla_mortalidad_hombre_2019!D10 -> 2.5 | K12: =tabla_mortalidad_hombre_2019!K10 -> 38.525594 | L12: =H12^F12 -> 0.98290417 | M12: =1-L12 -> 0.017095827 | N12: =N11*L11 -> 93344.2 | O12: =N12*M12 -> 1595.7963 | P12: =(((-5/24)*O11)+((2.5)*O12)+((5/24)*O13))/O12 -> 2.5918258 | Q12: =(C12*N13)+(P12*O12) -> 462878.05 | R12: =R13+Q12 -> 3724067.2 | S12: =R12/N12 -> 39.896075 | T12: =S12-K12 -> 1.3704811
B13: 40 | C13: 5 | D13: ='Defunciones generales'!D30 -> 802 | E13: =Homicidios!N35 -> 228.22419 | F13: =(D13-E13)/D13 -> 0.71543119 | G13: =tabla_mortalidad_hombre_2019!G11 -> 87266.505 | H13: =tabla_mortalidad_hombre_2019!F11 -> 0.9681157 | I13: =1-H13 -> 0.031884301 | J13: =tabla_mortalidad_hombre_2019!D11 -> 2.5 | K13: =tabla_mortalidad_hombre_2019!K11 -> 34.511046 | L13: =H13^F13 -> 0.97708405 | M13: =1-L13 -> 0.022915948 | N13: =N12*L12 -> 91748.404 | O13: =N13*M13 -> 2102.5016 | P13: =(((-5/24)*O12)+((2.5)*O13)+((5/24)*O14))/O13 -> 2.6056622 | Q13: =(C13*N14)+(P13*O13) -> 453707.92 | R13: =R14+Q13 -> 3261189.2 | S13: =R13/N13 -> 35.544915 | T13: =S13-K13 -> 1.0338683
B14: 45 | C14: 5 | D14: ='Defunciones generales'!D31 -> 877 | E14: =Homicidios!N36 -> 148.14553 | F14: =(D14-E14)/D14 -> 0.83107694 | G14: =tabla_mortalidad_hombre_2019!G12 -> 84484.074 | H14: =tabla_mortalidad_hombre_2019!F12 -> 0.96437654 | I14: =1-H14 -> 0.035623458 | J14: =tabla_mortalidad_hombre_2019!D12 -> 2.5 | K14: =tabla_mortalidad_hombre_2019!K12 -> 30.56531 | L14: =H14^F14 -> 0.97030383 | M14: =1-L14 -> 0.029696174 | N14: =N13*L13 -> 89645.902 | O14: =N14*M14 -> 2662.1403 | P14: =(((-5/24)*O13)+((2.5)*O14)+((5/24)*O15))/O14 -> 2.64478 | Q14: =(C14*N15)+(P14*O14) -> 441959.59 | R14: =R15+Q14 -> 2807481.3 | S14: =R14/N14 -> 31.317452 | T14: =S14-K14 -> 0.75214165
B15: 50 | C15: 5 | D15: ='Defunciones generales'!D32 -> 1072 | E15: =Homicidios!N37 -> 96.094395 | F15: =(D15-E15)/D15 -> 0.91035971 | G15: =tabla_mortalidad_hombre_2019!G13 -> 81474.459 | H15: =tabla_mortalidad_hombre_2019!F13 -> 0.95019891 | I15: =1-H15 -> 0.049801089 | J15: =tabla_mortalidad_hombre_2019!D13 -> 2.5 | K15: =tabla_mortalidad_hombre_2019!K13 -> 26.602025 | L15: =H15^F15 -> 0.95456002 | M15: =1-L15 -> 0.04543998 | N15: =N14*L14 -> 86983.762 | O15: =N15*M15 -> 3952.5404 | P15: =(((-5/24)*O14)+((2.5)*O15)+((5/24)*O16))/O15 -> 2.6405161 | Q15: =(C15*N16)+(P15*O15) -> 425592.86 | R15: =R16+Q15 -> 2365521.7 | S15: =R15/N15 -> 27.19498 | T15: =S15-K15 -> 0.59295475
B16: 55 | C16: 5 | D16: ='Defunciones generales'!D33 -> 1125 | E16: =Homicidios!N38 -> 44.043265 | F16: =(D16-E16)/D16 -> 0.96085043 | G16: =tabla_mortalidad_hombre_2019!G14 -> 77416.942 | H16: =tabla_mortalidad_hombre_2019!F14 -> 0.9333055 | I16: =1-H16 -> 0.066694501 | J16: =tabla_mortalidad_hombre_2019!D14 -> 2.5 | K16: =tabla_mortalidad_hombre_2019!K14 -> 22.865242 | L16: =H16^F16 -> 0.9358309 | M16: =1-L16 -> 0.064169104 | N16: =N15*L15 -> 83031.222 | O16: =N16*M16 -> 5328.0391 | P16: =(((-5/24)*O15)+((2.5)*O16)+((5/24)*O17))/O16 -> 2.6131103 | Q16: =(C16*N17)+(P16*O16) -> 402438.67 | R16: =R17+Q16 -> 1939928.8 | S16: =R16/N16 -> 23.363848 | T16: =S16-K16 -> 0.49860576
B17: 60 | C17: 5 | D17: ='Defunciones generales'!D34 -> 1221 | E17: =Homicidios!N39 -> 29.028515 | F17: =(D17-E17)/D17 -> 0.97622562 | G17: =tabla_mortalidad_hombre_2019!G15 -> 72253.658 | H17: =tabla_mortalidad_hombre_2019!F15 -> 0.90985891 | I17: =1-H17 -> 0.090141087 | J17: =tabla_mortalidad_hombre_2019!D15 -> 2.5 | K17: =tabla_mortalidad_hombre_2019!K15 -> 19.320553 | L17: =H17^F17 -> 0.91190463 | M17: =1-L17 -> 0.088095371 | N17: =N16*L16 -> 77703.183 | O17: =N17*M17 -> 6845.2907 | P17: =(((-5/24)*O16)+((2.5)*O17)+((5/24)*O18))/O17 -> 2.598516 | Q17: =(C17*N18)+(P17*O17) -> 372077.06 | R17: =R18+Q17 -> 1537490.1 | S17: =R17/N17 -> 19.786708 | T17: =S17-K17 -> 0.46615475
B18: 65 | C18: 5 | D18: ='Defunciones generales'!D35 -> 1205 | E18: =Homicidios!N40 -> 16.015733 | F18: =(D18-E18)/D18 -> 0.98670894 | G18: =tabla_mortalidad_hombre_2019!G16 -> 65740.635 | H18: =tabla_mortalidad_hombre_2019!F16 -> 0.87759976 | I18: =1-H18 -> 0.12240024 | J18: =tabla_mortalidad_hombre_2019!D16 -> 2.5 | K18: =tabla_mortalidad_hombre_2019!K16 -> 15.98699 | L18: =H18^F18 -> 0.87912401 | M18: =1-L18 -> 0.12087599 | N18: =N17*L17 -> 70857.892 | O18: =N18*M18 -> 8565.0175 | P18: =(((-5/24)*O17)+((2.5)*O18)+((5/24)*O19))/O18 -> 2.609886 | Q18: =(C18*N19)+(P18*O18) -> 333818.09 | R18: =R19+Q18 -> 1165413.1 | S18: =R18/N18 -> 16.447188 | T18: =S18-K18 -> 0.46019815
B19: 70 | C19: 5 | D19: ='Defunciones generales'!D36 -> 1360 | E19: =Homicidios!N41 -> 8.0078663 | F19: =(D19-E19)/D19 -> 0.99411186 | G19: =tabla_mortalidad_hombre_2019!G17 -> 57693.965 | H19: =tabla_mortalidad_hombre_2019!F17 -> 0.81661383 | I19: =1-H19 -> 0.18338617 | J19: =tabla_mortalidad_hombre_2019!D17 -> 2.5 | K19: =tabla_mortalidad_hombre_2019!K17 -> 12.868042 | L19: =H19^F19 -> 0.81758853 | M19: =1-L19 -> 0.18241147 | N19: =N18*L18 -> 62292.874 | O19: =N19*M19 -> 11362.935 | P19: =(((-5/24)*O18)+((2.5)*O19)+((5/24)*O20))/O19 -> 2.5790351 | Q19: =(C19*N20)+(P19*O19) -> 283955.1 | R19: =R20+Q19 -> 831595 | S19: =R19/N19 -> 13.349761 | T19: =S19-K19 -> 0.48171894
B20: 75 | C20: 5 | D20: ='Defunciones generales'!D37 -> 1336 | E20: =Homicidios!N42 -> 6.0058997 | F20: =(D20-E20)/D20 -> 0.99550457 | G20: =tabla_mortalidad_hombre_2019!G18 -> 47113.689 | H20: =tabla_mortalidad_hombre_2019!F18 -> 0.74620423 | I20: =1-H20 -> 0.25379577 | J20: =tabla_mortalidad_hombre_2019!D18 -> 2.5 | K20: =tabla_mortalidad_hombre_2019!K18 -> 10.196383 | L20: =H20^F20 -> 0.74718693 | M20: =1-L20 -> 0.25281307 | N20: =N19*L19 -> 50929.939 | O20: =N20*M20 -> 12875.754 | P20: =(((-5/24)*O19)+((2.5)*O20)+((5/24)*O21))/O20 -> 2.5541807 | Q20: =(C20*N21)+(P20*O20) -> 223157.93 | R20: =R21+Q20 -> 547639.9 | S20: =R20/N20 -> 10.752809 | T20: =S20-K20 -> 0.55642528
B21: 80 | C21: 5 | D21: ='Defunciones generales'!D38 -> 1335 | E21: =Homicidios!N43 -> 2.0019666 | F21: =(D21-E21)/D21 -> 0.9985004 | G21: =tabla_mortalidad_hombre_2019!G19 -> 35156.434 | H21: =tabla_mortalidad_hombre_2019!F19 -> 0.61295652 | I21: =1-H21 -> 0.38704348 | J21: =tabla_mortalidad_hombre_2019!D19 -> 2.5 | K21: =tabla_mortalidad_hombre_2019!K19 -> 7.8140443 | L21: =H21^F21 -> 0.61340659 | M21: =1-L21 -> 0.38659341 | N21: =N20*L20 -> 38054.185 | O21: =N21*M21 -> 14711.497 | P21: =C21+(F21*(I21/M21)*(J21-C21)) -> 2.5008429 | Q21: =(C21*N22)+(P21*O21) -> 153504.58 | R21: =R22+Q21 -> 324481.97 | S21: =R21/N21 -> 8.5268406 | T21: =S21-K21 -> 0.71279631
B22: 85 | C22: 5 | D22: ='Defunciones generales'!D39 -> 1477 | E22: =Homicidios!N44 -> 1.0009833 | F22: =(D22-E22)/D22 -> 0.99932229 | G22: =tabla_mortalidad_hombre_2019!G20 -> 21549.365 | H22: =tabla_mortalidad_hombre_2019!F20 -> 0 | I22: =1-H22 -> 1 | J22: =tabla_mortalidad_hombre_2019!D20 -> 0 | K22: =tabla_mortalidad_hombre_2019!K20 -> 6.169529 | L22: =H22^F22 -> 0 | M22: =1-L22 -> 1 | N22: =N21*L21 -> 23342.688 | O22: =N22*M22 -> 23342.688 | P22: =K22/F22 -> 6.173713 | Q22: =N22/[1]LT!E39 -> 170977.39 | R22: =Q22 -> 170977.39 | S22: =R22/N22 -> 7.3246658 | T22: =S22-K22 -> 1.1551368
B24: Mujeres, 2019
B26: Age x | C26: n | D26: nDx | E26: nDxi | I26: nqx | K26: e0 | M26: nqx_i | O26: ndx_i | Q26: L | R26: T | S26: e0_i | T26: diff | AA26: Hombres | AB26: Mujeres
B27: 0 | C27: 1 | D27: ='Defunciones generales'!D78 -> 374 | E27: =Homicidios!N83 -> 1 | F27: =(D27-E27)/D27 -> 0.9973262 | G27: =tabla_mortalidad_mujer_2019!G2 -> 100000 | H27: =tabla_mortalidad_mujer_2019!F2 -> 0.98525343 | I27: =1-H27 -> 0.01474657 | J27: =tabla_mortalidad_mujer_2019!D2 -> 0.09484899 | K27: =tabla_mortalidad_mujer_2019!K2 -> 76.707837 | L27: =H27^F27 -> 0.98529257 | M27: =1-L27 -> 0.014707432 | N27: 100000 | O27: =N27*M27 -> 1470.7432 | P27: =C27+(F27*(I27/M27)*(J27-C27)) -> 0.094866923 | Q27: =(C27*N28)+(P27*O27) -> 98668.782 | R27: =R28+Q27 -> 7756669.7 | S27: =R27/N27 -> 77.566697 | T27: =S27-K27 -> 0.85886031 | Z27: Sin homicidios | AA27: =S4 -> 71.089013 | AB27: =S27 -> 77.566697
B28: 1 | C28: 4 | D28: ='Defunciones generales'!D79 -> 85 | E28: =Homicidios!N84 -> 4 | F28: =(D28-E28)/D28 -> 0.95294118 | G28: =tabla_mortalidad_mujer_2019!G3 -> 98525.343 | H28: =tabla_mortalidad_mujer_2019!F3 -> 0.99717894 | I28: =1-H28 -> 0.0028210638 | J28: =tabla_mortalidad_mujer_2019!D3 -> 1.4993119 | K28: =tabla_mortalidad_mujer_2019!K3 -> 76.854525 | L28: =H28^F28 -> 0.99731151 | M28: =1-L28 -> 0.0026884865 | N28: =N27*L27 -> 98529.257 | O28: =N28*M28 -> 264.89458 | P28: =C28+(F28*(I28/M28)*(J28-C28)) -> 1.499478 | Q28: =(C28*N29)+(P28*O28) -> 393454.65 | R28: =R29+Q28 -> 7658000.9 | S28: =R28/N28 -> 77.723117 | T28: =S28-K28 -> 0.86859144 | V28: Número de años que se espera que viva una mujer de 0 años hasta llegar a los 85 años. | Z28: Con homicidios | AA28: =K4 -> 68.046242 | AB28: =K27 -> 76.707837
B29: 5 | C29: 5 | D29: ='Defunciones generales'!D80 -> 43 | E29: =Homicidios!N85 -> 2 | F29: =(D29-E29)/D29 -> 0.95348837 | G29: =tabla_mortalidad_mujer_2019!G4 -> 98247.397 | H29: =tabla_mortalidad_mujer_2019!F4 -> 0.99863484 | I29: =1-H29 -> 0.0013651625 | J29: =tabla_mortalidad_mujer_2019!D4 -> 2.5 | K29: =tabla_mortalidad_mujer_2019!K4 -> 73.067709 | L29: =H29^F29 -> 0.99869829 | M29: =1-L29 -> 0.0013017079 | N29: =N28*L28 -> 98264.362 | O29: =N29*M29 -> 127.9115 | P29: =C29+(F29*(I29/M29)*(J29-C29)) -> 2.5000794 | Q29: =(C29*N30)+(P29*O29) -> 491002.04 | R29: =R30+Q29 -> 7264546.3 | S29: =R29/N29 -> 73.928596 | T29: =S29-K29 -> 0.86088682 | AA29: =AA27-AA28 -> 3.0427709 | AB29: =AB27-AB28 -> 0.85886031
B30: 10 | C30: 5 | D30: ='Defunciones generales'!D81 -> 51 | E30: =Homicidios!N86 -> 6 | F30: =(D30-E30)/D30 -> 0.88235294 | G30: =tabla_mortalidad_mujer_2019!G5 -> 98113.273 | H30: =tabla_mortalidad_mujer_2019!F5 -> 0.99845073 | I30: =1-H30 -> 0.001549269 | J30: =tabla_mortalidad_mujer_2019!D5 -> 2.5 | K30: =tabla_mortalidad_mujer_2019!K5 -> 68.164177 | L30: =H30^F30 -> 0.99863287 | M30: =1-L30 -> 0.0013671267 | N30: =N29*L29 -> 98136.451 | O30: =N30*M30 -> 134.16496 | P30: =(((-5/24)*O29)+((2.5)*O30)+((5/24)*O31))/O30 -> 2.7544347 | Q30: =(C30*N31)+(P30*O30) -> 490380.98 | R30: =R31+Q30 -> 6773544.2 | S30: =R30/N30 -> 69.021696 | T30: =S30-K30 -> 0.85751899
B31: 15 | C31: 5 | D31: ='Defunciones generales'!D82 -> 135 | E31: =Homicidios!N87 -> 39 | F31: =(D31-E31)/D31 -> 0.71111111 | G31: =tabla_mortalidad_mujer_2019!G6 -> 97961.269 | H31: =tabla_mortalidad_mujer_2019!F6 -> 0.99581595 | I31: =1-H31 -> 0.0041840535 | J31: =tabla_mortalidad_mujer_2019!D6 -> 2.5 | K31: =tabla_mortalidad_mujer_2019!K6 -> 63.266066 | L31: =H31^F31 -> 0.99702287 | M31: =1-L31 -> 0.0029771284 | N31: =N30*L30 -> 98002.286 | O31: =N31*M31 -> 291.76538 | P31: =(((-5/24)*O30)+((2.5)*O31)+((5/24)*O32))/O31 -> 2.653605 | Q31: =(C31*N32)+(P31*O31) -> 489326.83 | R31: =R32+Q31 -> 6283163.3 | S31: =R31/N31 -> 64.112416 | T31: =S31-K31 -> 0.84634943 | V31: Sin COVID | W31: Con COVID
B32: 20 | C32: 5 | D32: ='Defunciones generales'!D83 -> 178 | E32: =Homicidios!N88 -> 66 | F32: =(D32-E32)/D32 -> 0.62921348 | G32: =tabla_mortalidad_mujer_2019!G7 -> 97551.394 | H32: =tabla_mortalidad_mujer_2019!F7 -> 0.99432478 | I32: =1-H32 -> 0.0056752151 | J32: =tabla_mortalidad_mujer_2019!D7 -> 2.5 | K32: =tabla_mortalidad_mujer_2019!K7 -> 58.521383 | L32: =H32^F32 -> 0.99642531 | M32: =1-L32 -> 0.0035746888 | N32: =N31*L31 -> 97710.52 | O32: =N32*M32 -> 349.2847 | P32: =(((-5/24)*O31)+((2.5)*O32)+((5/24)*O33))/O32 -> 2.5665207 | Q32: =(C32*N33)+(P32*O32) -> 487702.62 | R32: =R33+Q32 -> 5793836.4 | S32: =R32/N32 -> 59.295933 | T32: =S32-K32 -> 0.77454982 | V32: =([2]TV!M29-[2]TV!M47)/[2]TV!J29 -> 73.3257 | W32: =(R27-R45)/N27 -> 74.695009
B33: 25 | C33: 5 | D33: ='Defunciones generales'!D84 -> 158 | E33: =Homicidios!N89 -> 34 | F33: =(D33-E33)/D33 -> 0.78481013 | G33: =tabla_mortalidad_mujer_2019!G8 -> 96997.769 | H33: =tabla_mortalidad_mujer_2019!F8 -> 0.99472501 | I33: =1-H33 -> 0.0052749904 | J33: =tabla_mortalidad_mujer_2019!D8 -> 2.5 | K33: =tabla_mortalidad_mujer_2019!K8 -> 53.841131 | L33: =H33^F33 -> 0.99585778 | M33: =1-L33 -> 0.0041422206 | N33: =N32*L32 -> 97361.236 | O33: =N33*M33 -> 403.29171 | P33: =(((-5/24)*O32)+((2.5)*O33)+((5/24)*O34))/O33 -> 2.5665287 | Q33: =(C33*N34)+(P33*O33) -> 485824.78 | R33: =R34+Q33 -> 5306133.8 | S33: =R33/N33 -> 54.49945 | T33: =S33-K33 -> 0.65831929 | V33: Diff | W33: =W32-V32 -> 1.3693092
B34: 30 | C34: 5 | D34: ='Defunciones generales'!D85 -> 171 | E34: =Homicidios!N90 -> 33 | F34: =(D34-E34)/D34 -> 0.80701754 | G34: =tabla_mortalidad_mujer_2019!G9 -> 96486.107 | H34: =tabla_mortalidad_mujer_2019!F9 -> 0.99389382 | I34: =1-H34 -> 0.0061061802 | J34: =tabla_mortalidad_mujer_2019!D9 -> 2.5 | K34: =tabla_mortalidad_mujer_2019!K9 -> 49.113391 | L34: =H34^F34 -> 0.99506929 | M34: =1-L34 -> 0.004930705 | N34: =N33*L33 -> 96957.944 | O34: =N34*M34 -> 478.07102 | P34: =(((-5/24)*O33)+((2.5)*O34)+((5/24)*O35))/O34 -> 2.6067612 | Q34: =(C34*N35)+(P34*O34) -> 483645.58 | R34: =R35+Q34 -> 4820309 | S34: =R34/N34 -> 49.715463 | T34: =S34-K34 -> 0.60207153
B35: 35 | C35: 5 | D35: ='Defunciones generales'!D86 -> 205 | E35: =Homicidios!N91 -> 25 | F35: =(D35-E35)/D35 -> 0.87804878 | G35: =tabla_mortalidad_mujer_2019!G10 -> 95896.945 | H35: =tabla_mortalidad_mujer_2019!F10 -> 0.992351 | I35: =1-H35 -> 0.0076490041 | J35: =tabla_mortalidad_mujer_2019!D10 -> 2.5 | K35: =tabla_mortalidad_mujer_2019!K10 -> 44.399769 | L35: =H35^F35 -> 0.99328066 | M35: =1-L35 -> 0.0067193401 | N35: =N34*L34 -> 96479.873 | O35: =N35*M35 -> 648.28108 | P35: =(((-5/24)*O34)+((2.5)*O35)+((5/24)*O36))/O35 -> 2.6971514 | Q35: =(C35*N36)+(P35*O35) -> 480906.47 | R35: =R36+Q35 -> 4336663.5 | S35: =R35/N35 -> 44.948893 | T35: =S35-K35 -> 0.54912317
B36: 40 | C36: 5 | D36: ='Defunciones generales'!D87 -> 304 | E36: =Homicidios!N92 -> 13 | F36: =(D36-E36)/D36 -> 0.95723684 | G36: =tabla_mortalidad_mujer_2019!G11 -> 95163.429 | H36: =tabla_mortalidad_mujer_2019!F11 -> 0.98810383 | I36: =1-H36 -> 0.011896172 | J36: =tabla_mortalidad_mujer_2019!D11 -> 2.5 | K36: =tabla_mortalidad_mujer_2019!K11 -> 39.722731 | L36: =H36^F36 -> 0.98860964 | M36: =1-L36 -> 0.011390363 | N36: =N35*L35 -> 95831.592 | O36: =N36*M36 -> 1091.5566 | P36: =(((-5/24)*O35)+((2.5)*O36)+((5/24)*O37))/O36 -> 2.6255455 | Q36: =(C36*N37)+(P36*O36) -> 476566.11 | R36: =R37+Q36 -> 3855757 | S36: =R36/N36 -> 40.234717 | T36: =S36-K36 -> 0.5119857
B37: 45 | C37: 5 | D37: ='Defunciones generales'!D88 -> 360 | E37: =Homicidios!N93 -> 18 | F37: =(D37-E37)/D37 -> 0.95 | G37: =tabla_mortalidad_mujer_2019!G12 -> 94031.348 | H37: =tabla_mortalidad_mujer_2019!F12 -> 0.98549385 | I37: =1-H37 -> 0.014506147 | J37: =tabla_mortalidad_mujer_2019!D12 -> 2.5 | K37: =tabla_mortalidad_mujer_2019!K12 -> 35.17087 | L37: =H37^F37 -> 0.98621414 | M37: =1-L37 -> 0.013785863 | N37: =N36*L36 -> 94740.035 | O37: =N37*M37 -> 1306.0731 | P37: =(((-5/24)*O36)+((2.5)*O37)+((5/24)*O38))/O37 -> 2.67151 | Q37: =(C37*N38)+(P37*O37) -> 470659 | R37: =R38+Q37 -> 3379190.9 | S37: =R37/N37 -> 35.668035 | T37: =S37-K37 -> 0.49716429
B38: 50 | C38: 5 | D38: ='Defunciones generales'!D89 -> 518 | E38: =Homicidios!N94 -> 3 | F38: =(D38-E38)/D38 -> 0.99420849 | G38: =tabla_mortalidad_mujer_2019!G13 -> 92667.316 | H38: =tabla_mortalidad_mujer_2019!F13 -> 0.97667601 | I38: =1-H38 -> 0.023323986 | J38: =tabla_mortalidad_mujer_2019!D13 -> 2.5 | K38: =tabla_mortalidad_mujer_2019!K13 -> 30.651775 | L38: =H38^F38 -> 0.97680952 | M38: =1-L38 -> 0.023190484 | N38: =N37*L37 -> 93433.962 | O38: =N38*M38 -> 2166.7788 | P38: =(((-5/24)*O37)+((2.5)*O38)+((5/24)*O39))/O38 -> 2.6923466 | Q38: =(C38*N39)+(P38*O38) -> 462169.64 | R38: =R39+Q38 -> 2908531.9 | S38: =R38/N38 -> 31.129279 | T38: =S38-K38 -> 0.47750399
B39: 55 | C39: 5 | D39: ='Defunciones generales'!D90 -> 647 | E39: =Homicidios!N95 -> 5 | F39: =(D39-E39)/D39 -> 0.99227202 | G39: =tabla_mortalidad_mujer_2019!G14 -> 90505.945 | H39: =tabla_mortalidad_mujer_2019!F14 -> 0.96349336 | I39: =1-H39 -> 0.036506638 | J39: =tabla_mortalidad_mujer_2019!D14 -> 2.5 | K39: =tabla_mortalidad_mujer_2019!K14 -> 26.324067 | L39: =H39^F39 -> 0.96377031 | M39: =1-L39 -> 0.036229689 | N39: =N38*L38 -> 91267.183 | O39: =N39*M39 -> 3306.5817 | P39: =(((-5/24)*O38)+((2.5)*O39)+((5/24)*O40))/O39 -> 2.6706057 | Q39: =(C39*N40)+(P39*O39) -> 448633.58 | R39: =R40+Q39 -> 2446362.2 | S39: =R39/N39 -> 26.804402 | T39: =S39-K39 -> 0.48033448
B40: 60 | C40: 5 | D40: ='Defunciones generales'!D91 -> 827 | E40: =Homicidios!N96 -> 4 | F40: =(D40-E40)/D40 -> 0.99516324 | G40: =tabla_mortalidad_mujer_2019!G15 -> 87201.877 | H40: =tabla_mortalidad_mujer_2019!F15 -> 0.94432073 | I40: =1-H40 -> 0.055679274 | J40: =tabla_mortalidad_mujer_2019!D15 -> 2.5 | K40: =tabla_mortalidad_mujer_2019!K15 -> 22.226758 | L40: =H40^F40 -> 0.94458243 | M40: =1-L40 -> 0.055417572 | N40: =N39*L39 -> 87960.602 | O40: =N40*M40 -> 4874.5629 | P40: =(((-5/24)*O39)+((2.5)*O40)+((5/24)*O41))/O40 -> 2.6512332 | Q40: =(C40*N41)+(P40*O40) -> 428353.8 | R40: =R41+Q40 -> 1997728.7 | S40: =R40/N40 -> 22.71163 | T40: =S40-K40 -> 0.48487222
B41: 65 | C41: 5 | D41: ='Defunciones generales'!D92 -> 902 | E41: =Homicidios!N97 -> 2 | F41: =(D41-E41)/D41 -> 0.99778271 | G41: =tabla_mortalidad_mujer_2019!G16 -> 82346.54 | H41: =tabla_mortalidad_mujer_2019!F16 -> 0.91743875 | I41: =1-H41 -> 0.082561246 | J41: =tabla_mortalidad_mujer_2019!D16 -> 2.5 | K41: =tabla_mortalidad_mujer_2019!K16 -> 18.389892 | L41: =H41^F41 -> 0.91761406 | M41: =1-L41 -> 0.08238594 | N41: =N40*L40 -> 83086.039 | O41: =N41*M41 -> 6845.1214 | P41: =(((-5/24)*O40)+((2.5)*O41)+((5/24)*O42))/O41 -> 2.6487408 | Q41: =(C41*N42)+(P41*O41) -> 399335.54 | R41: =R42+Q41 -> 1569374.9 | S41: =R41/N41 -> 18.888551 | T41: =S41-K41 -> 0.49865875
B42: 70 | C42: 5 | D42: ='Defunciones generales'!D93 -> 1068 | E42: =Homicidios!N98 -> 1 | F42: =(D42-E42)/D42 -> 0.99906367 | G42: =tabla_mortalidad_mujer_2019!G17 -> 75547.907 | H42: =tabla_mortalidad_mujer_2019!F17 -> 0.87185079 | I42: =1-H42 -> 0.12814921 | J42: =tabla_mortalidad_mujer_2019!D17 -> 2.5 | K42: =tabla_mortalidad_mujer_2019!K17 -> 14.81984 | L42: =H42^F42 -> 0.87196275 | M42: =1-L42 -> 0.12803725 | N42: =N41*L41 -> 76240.917 | O42: =N42*M42 -> 9761.6774 | P42: =(((-5/24)*O41)+((2.5)*O42)+((5/24)*O43))/O42 -> 2.6412069 | Q42: =(C42*N43)+(P42*O42) -> 358178.81 | R42: =R43+Q42 -> 1170039.3 | S42: =R42/N42 -> 15.346606 | T42: =S42-K42 -> 0.52676649
B43: 75 | C43: 5 | D43: ='Defunciones generales'!D94 -> 1178 | E43: =Homicidios!N99 -> 1 | F43: =(D43-E43)/D43 -> 0.9991511 | G43: =tabla_mortalidad_mujer_2019!G18 -> 65866.502 | H43: =tabla_mortalidad_mujer_2019!F18 -> 0.7973546 | I43: =1-H43 -> 0.2026454 | J43: =tabla_mortalidad_mujer_2019!D18 -> 2.5 | K43: =tabla_mortalidad_mujer_2019!K18 -> 11.630674 | L43: =H43^F43 -> 0.7975079 | M43: =1-L43 -> 0.2024921 | N43: =N42*L42 -> 66479.24 | O43: =N43*M43 -> 13461.521 | P43: =(((-5/24)*O42)+((2.5)*O43)+((5/24)*O44))/O43 -> 2.5995489 | Q43: =(C43*N44)+(P43*O43) -> 300082.48 | R43: =R44+Q43 -> 811860.51 | S43: =R43/N43 -> 12.212241 | T43: =S43-K43 -> 0.58156694
...

Sheet DM_2010
B2: Hombres, 2019
B3: Age x | C3: n | D3: nDx | E3: nDxi | I3: nqx | K3: e0 | M3: nqx_i | O3: ndx_i | Q3: L | R3: T | S3: e0_i | T3: diff
B4: 0 | C4: 1 | D4: ='Defunciones generales'!D2 -> 518 | E4: =Homicidios!N7 -> 3.0335047 | F4: =(D4-E4)/D4 -> 0.99414381 | G4: =tabla_mortalidad_hombre_2010!G2 -> 100000 | H4: =tabla_mortalidad_hombre_2010!F2 -> 0.98332588 | I4: =1-H4 -> 0.016674118 | J4: =tabla_mortalidad_hombre_2010!D2 -> 0.090442517 | K4: =tabla_mortalidad_hombre_2010!K2 -> 62.494617 | L4: =H4^F4 -> 0.98342271 | M4: =1-L4 -> 0.016577285 | N4: 100000 | O4: =N4*M4 -> 1657.7285 | P4: =C4+(F4*(I4/M4)*(J4-C4)) -> 0.090487173 | Q4: =(C4*N5)+(P4*O4) -> 98492.275 | R4: =R5+Q4 -> 7067606.8 | S4: =R4/N4 -> 70.676068 | T4: =S4-K4 -> 8.1814516
B5: 1 | C5: 4 | D5: ='Defunciones generales'!D3 -> 114 | E5: =Homicidios!N8 -> 13.145187 | F5: =(D5-E5)/D5 -> 0.88469134 | G5: =tabla_mortalidad_hombre_2010!G3 -> 98332.588 | H5: =tabla_mortalidad_hombre_2010!F3 -> 0.99670358 | I5: =1-H5 -> 0.0032964163 | J5: =tabla_mortalidad_hombre_2010!D3 -> 1.6033226 | K5: =tabla_mortalidad_hombre_2010!K3 -> 62.552796 | L5: =H5^F5 -> 0.99708313 | M5: =1-L5 -> 0.0029168659 | N5: =N4*L4 -> 98342.271 | O5: =N5*M5 -> 286.85122 | P5: =C5+(F5*(I5/M5)*(J5-C5)) -> 1.6037786 | Q5: =(C5*N6)+(P5*O5) -> 392681.73 | R5: =R6+Q5 -> 6969114.6 | S5: =R5/N5 -> 70.86591 | T5: =S5-K5 -> 8.3131144 | V5: Número de años que se espera que viva un hombre de 0 años hasta llegar a los 85 años.
B6: 5 | C6: 5 | D6: ='Defunciones generales'!D4 -> 68 | E6: =Homicidios!N9 -> 6.0670094 | F6: =(D6-E6)/D6 -> 0.91077927 | G6: =tabla_mortalidad_hombre_2010!G4 -> 98008.443 | H6: =tabla_mortalidad_hombre_2010!F4 -> 0.99806762 | I6: =1-H6 -> 0.0019323811 | J6: =tabla_mortalidad_hombre_2010!D4 -> 2.5 | K6: =tabla_mortalidad_hombre_2010!K4 -> 58.754375 | L6: =H6^F6 -> 0.99823988 | M6: =1-L6 -> 0.0017601245 | N6: =N5*L5 -> 98055.42 | O6: =N6*M6 -> 172.58975 | P6: =C6+(F6*(I6/M6)*(J6-C6)) -> 2.5002156 | Q6: =(C6*N7)+(P6*O6) -> 489845.66 | R6: =R7+Q6 -> 6576432.8 | S6: =R6/N6 -> 67.068529 | T6: =S6-K6 -> 8.3141545
B7: 10 | C7: 5 | D7: ='Defunciones generales'!D5 -> 120 | E7: =Homicidios!N10 -> 37.413225 | F7: =(D7-E7)/D7 -> 0.68822313 | G7: =tabla_mortalidad_hombre_2010!G5 -> 97819.053 | H7: =tabla_mortalidad_hombre_2010!F5 -> 0.99647572 | I7: =1-H7 -> 0.0035242837 | J7: =tabla_mortalidad_hombre_2010!D5 -> 2.5 | K7: =tabla_mortalidad_hombre_2010!K5 -> 53.86329 | L7: =H7^F7 -> 0.99757317 | M7: =1-L7 -> 0.0024268282 | N7: =N6*L6 -> 97882.831 | O7: =N7*M7 -> 237.54481 | P7: =(((-5/24)*O6)+((2.5)*O7)+((5/24)*O8))/O7 -> 2.9266239 | Q7: =(C7*N8)+(P7*O7) -> 488921.63 | R7: =R8+Q7 -> 6086587.2 | S7: =R7/N7 -> 62.182378 | T7: =S7-K7 -> 8.3190878
B8: 15 | C8: 5 | D8: ='Defunciones generales'!D6 -> 770 | E8: =Homicidios!N11 -> 542.99734 | F8: =(D8-E8)/D8 -> 0.29480865 | G8: =tabla_mortalidad_hombre_2010!G6 -> 97474.311 | H8: =tabla_mortalidad_hombre_2010!F6 -> 0.97729055 | I8: =1-H8 -> 0.022709449 | J8: =tabla_mortalidad_hombre_2010!D6 -> 2.5 | K8: =tabla_mortalidad_hombre_2010!K6 -> 49.044949 | L8: =H8^F8 -> 0.99325075 | M8: =1-L8 -> 0.0067492528 | N8: =N7*L7 -> 97645.286 | O8: =N8*M8 -> 659.03272 | P8: =(((-5/24)*O7)+((2.5)*O8)+((5/24)*O9))/O8 -> 2.7415941 | Q8: =(C8*N9)+(P8*O8) -> 486738.07 | R8: =R9+Q8 -> 5597665.5 | S8: =R8/N8 -> 57.326531 | T8: =S8-K8 -> 8.2815821 | V8: Sin COVID | W8: Con COVID
B9: 20 | C9: 5 | D9: ='Defunciones generales'!D7 -> 1277 | E9: =Homicidios!N12 -> 970.7215 | F9: =(D9-E9)/D9 -> 0.23984221 | G9: =tabla_mortalidad_hombre_2010!G7 -> 95260.723 | H9: =tabla_mortalidad_hombre_2010!F7 -> 0.95763294 | I9: =1-H9 -> 0.042367063 | J9: =tabla_mortalidad_hombre_2010!D7 -> 2.5 | K9: =tabla_mortalidad_hombre_2010!K7 -> 45.126521 | L9: =H9^F9 -> 0.98967077 | M9: =1-L9 -> 0.010329227 | N9: =N8*L8 -> 96986.253 | O9: =N9*M9 -> 1001.7931 | P9: =(((-5/24)*O8)+((2.5)*O9)+((5/24)*O10))/O9 -> 2.6330656 | Q9: =(C9*N10)+(P9*O9) -> 482560.09 | R9: =R10+Q9 -> 5110927.5 | S9: =R9/N9 -> 52.697442 | T9: =S9-K9 -> 7.570921 | V9: =([2]TV!M53-[2]TV!M71)/[2]TV!J53 -> 66.401396 | W9: =(R4-R22)/N4 -> 69.09549
B10: 25 | C10: 5 | D10: ='Defunciones generales'!D8 -> 1405 | E10: =Homicidios!N13 -> 1049.5926 | F10: =(D10-E10)/D10 -> 0.25295899 | G10: =tabla_mortalidad_hombre_2010!G8 -> 91224.806 | H10: =tabla_mortalidad_hombre_2010!F8 -> 0.94756344 | I10: =1-H10 -> 0.052436558 | J10: =tabla_mortalidad_hombre_2010!D8 -> 2.5 | K10: =tabla_mortalidad_hombre_2010!K8 -> 42.01238 | L10: =H10^F10 -> 0.98646767 | M10: =1-L10 -> 0.013532325 | N10: =N9*L9 -> 95984.46 | O10: =N10*M10 -> 1298.893 | P10: =(((-5/24)*O9)+((2.5)*O10)+((5/24)*O11))/O10 -> 2.5812379 | Q10: =(C10*N11)+(P10*O10) -> 476780.59 | R10: =R11+Q10 -> 4628367.4 | S10: =R10/N10 -> 48.219966 | T10: =S10-K10 -> 6.2075858 | V10: Diff | W10: =W9-V9 -> 2.694094
B11: 30 | C11: 5 | D11: ='Defunciones generales'!D9 -> 1474 | E11: =Homicidios!N14 -> 1062.7378 | F11: =(D11-E11)/D11 -> 0.27901098 | G11: =tabla_mortalidad_hombre_2010!G9 -> 86441.291 | H11: =tabla_mortalidad_hombre_2010!F9 -> 0.94407274 | I11: =1-H11 -> 0.05592726 | J11: =tabla_mortalidad_hombre_2010!D9 -> 2.5 | K11: =tabla_mortalidad_hombre_2010!K9 -> 39.198929 | L11: =H11^F11 -> 0.98407058 | M11: =1-L11 -> 0.01592942 | N11: =N10*L10 -> 94685.567 | O11: =N11*M11 -> 1508.2862 | P11: =(((-5/24)*O10)+((2.5)*O11)+((5/24)*O12))/O11 -> 2.5489322 | Q11: =(C11*N12)+(P11*O11) -> 469730.92 | R11: =R12+Q11 -> 4151586.8 | S11: =R11/N11 -> 43.846036 | T11: =S11-K11 -> 4.6471078
B12: 35 | C12: 5 | D12: ='Defunciones generales'!D10 -> 1265 | E12: =Homicidios!N15 -> 790.73356 | F12: =(D12-E12)/D12 -> 0.37491418 | G12: =tabla_mortalidad_hombre_2010!G10 -> 81606.867 | H12: =tabla_mortalidad_hombre_2010!F10 -> 0.95337433 | I12: =1-H12 -> 0.046625668 | J12: =tabla_mortalidad_hombre_2010!D10 -> 2.5 | K12: =tabla_mortalidad_hombre_2010!K10 -> 36.372988 | L12: =H12^F12 -> 0.982258 | M12: =1-L12 -> 0.017741999 | N12: =N11*L11 -> 93177.281 | O12: =N12*M12 -> 1653.1512 | P12: =(((-5/24)*O11)+((2.5)*O12)+((5/24)*O13))/O12 -> 2.5874028 | Q12: =(C12*N13)+(P12*O12) -> 461898.02 | R12: =R13+Q12 -> 3681855.9 | S12: =R12/N12 -> 39.514524 | T12: =S12-K12 -> 3.1415356
B13: 40 | C13: 5 | D13: ='Defunciones generales'!D11 -> 1048 | E13: =Homicidios!N16 -> 495.47243 | F13: =(D13-E13)/D13 -> 0.52722096 | G13: =tabla_mortalidad_hombre_2010!G11 -> 77801.892 | H13: =tabla_mortalidad_hombre_2010!F11 -> 0.95486191 | I13: =1-H13 -> 0.045138094 | J13: =tabla_mortalidad_hombre_2010!D11 -> 2.5 | K13: =tabla_mortalidad_hombre_2010!K11 -> 33.029579 | L13: =H13^F13 -> 0.97594254 | M13: =1-L13 -> 0.024057464 | N13: =N12*L12 -> 91524.13 | O13: =N13*M13 -> 2201.8385 | P13: =(((-5/24)*O12)+((2.5)*O13)+((5/24)*O14))/O13 -> 2.574566 | Q13: =(C13*N14)+(P13*O13) -> 452280.23 | R13: =R14+Q13 -> 3219957.9 | S13: =R13/N13 -> 35.181519 | T13: =S13-K13 -> 2.15194
B14: 45 | C14: 5 | D14: ='Defunciones generales'!D12 -> 821 | E14: =Homicidios!N17 -> 309.41748 | F14: =(D14-E14)/D14 -> 0.62312122 | G14: =tabla_mortalidad_hombre_2010!G12 -> 74290.063 | H14: =tabla_mortalidad_hombre_2010!F12 -> 0.95650312 | I14: =1-H14 -> 0.043496884 | J14: =tabla_mortalidad_hombre_2010!D12 -> 2.5 | K14: =tabla_mortalidad_hombre_2010!K12 -> 29.472768 | L14: =H14^F14 -> 0.97266946 | M14: =1-L14 -> 0.027330542 | N14: =N13*L13 -> 89322.291 | O14: =N14*M14 -> 2441.2266 | P14: =(((-5/24)*O13)+((2.5)*O14)+((5/24)*O15))/O14 -> 2.6128399 | Q14: =(C14*N15)+(P14*O14) -> 440783.86 | R14: =R15+Q14 -> 2767677.6 | S14: =R14/N14 -> 30.985296 | T14: =S14-K14 -> 1.5125277
B15: 50 | C15: 5 | D15: ='Defunciones generales'!D13 -> 795 | E15: =Homicidios!N18 -> 178.97678 | F15: =(D15-E15)/D15 -> 0.77487198 | G15: =tabla_mortalidad_hombre_2010!G13 -> 71058.677 | H15: =tabla_mortalidad_hombre_2010!F13 -> 0.94796454 | I15: =1-H15 -> 0.052035456 | J15: =tabla_mortalidad_hombre_2010!D13 -> 2.5 | K15: =tabla_mortalidad_hombre_2010!K13 -> 25.699352 | L15: =H15^F15 -> 0.95943784 | M15: =1-L15 -> 0.040562157 | N15: =N14*L14 -> 86881.065 | O15: =N15*M15 -> 3524.0834 | P15: =(((-5/24)*O14)+((2.5)*O15)+((5/24)*O16))/O15 -> 2.6735725 | Q15: =(C15*N16)+(P15*O15) -> 426206.8 | R15: =R16+Q15 -> 2326893.8 | S15: =R15/N15 -> 26.782519 | T15: =S15-K15 -> 1.0831668
B16: 55 | C16: 5 | D16: ='Defunciones generales'!D14 -> 812 | E16: =Homicidios!N19 -> 91.005141 | F16: =(D16-E16)/D16 -> 0.8879247 | G16: =tabla_mortalidad_hombre_2010!G14 -> 67361.106 | H16: =tabla_mortalidad_hombre_2010!F14 -> 0.92764963 | I16: =1-H16 -> 0.072350372 | J16: =tabla_mortalidad_hombre_2010!D14 -> 2.5 | K16: =tabla_mortalidad_hombre_2010!K14 -> 21.972806 | L16: =H16^F16 -> 0.93549059 | M16: =1-L16 -> 0.064509406 | N16: =N15*L15 -> 83356.981 | O16: =N16*M16 -> 5377.3093 | P16: =(((-5/24)*O15)+((2.5)*O16)+((5/24)*O17))/O16 -> 2.6258779 | Q16: =(C16*N17)+(P16*O16) -> 404018.52 | R16: =R17+Q16 -> 1900687 | S16: =R16/N16 -> 22.801773 | T16: =S16-K16 -> 0.82896726
B17: 60 | C17: 5 | D17: ='Defunciones generales'!D15 -> 848 | E17: =Homicidios!N20 -> 49.547243 | F17: =(D17-E17)/D17 -> 0.94157165 | G17: =tabla_mortalidad_hombre_2010!G15 -> 62487.505 | H17: =tabla_mortalidad_hombre_2010!F15 -> 0.90800817 | I17: =1-H17 -> 0.091991828 | J17: =tabla_mortalidad_hombre_2010!D15 -> 2.5 | K17: =tabla_mortalidad_hombre_2010!K15 -> 18.491553 | L17: =H17^F17 -> 0.91314239 | M17: =1-L17 -> 0.086857611 | N17: =N16*L16 -> 77979.672 | O17: =N17*M17 -> 6773.128 | P17: =(((-5/24)*O16)+((2.5)*O17)+((5/24)*O18))/O17 -> 2.6492877 | Q17: =(C17*N18)+(P17*O17) -> 373976.68 | R17: =R18+Q17 -> 1496668.5 | S17: =R17/N17 -> 19.193059 | T17: =S17-K17 -> 0.70150666
B18: 65 | C18: 5 | D18: ='Defunciones generales'!D16 -> 1094 | E18: =Homicidios!N21 -> 44.491402 | F18: =(D18-E18)/D18 -> 0.95933144 | G18: =tabla_mortalidad_hombre_2010!G16 -> 56739.165 | H18: =tabla_mortalidad_hombre_2010!F16 -> 0.85070988 | I18: =1-H18 -> 0.14929012 | J18: =tabla_mortalidad_hombre_2010!D16 -> 2.5 | K18: =tabla_mortalidad_hombre_2010!K16 -> 15.111684 | L18: =H18^F18 -> 0.85632212 | M18: =1-L18 -> 0.14367788 | N18: =N17*L17 -> 71206.544 | O18: =N18*M18 -> 10230.805 | P18: =(((-5/24)*O17)+((2.5)*O18)+((5/24)*O19))/O18 -> 2.5949045 | Q18: =(C18*N19)+(P18*O18) -> 331426.66 | R18: =R19+Q18 -> 1122691.8 | S18: =R18/N18 -> 15.766694 | T18: =S18-K18 -> 0.65501031
B19: 70 | C19: 5 | D19: ='Defunciones generales'!D17 -> 1149 | E19: =Homicidios!N22 -> 26.290374 | F19: =(D19-E19)/D19 -> 0.97711891 | G19: =tabla_mortalidad_hombre_2010!G17 -> 48268.569 | H19: =tabla_mortalidad_hombre_2010!F17 -> 0.80854674 | I19: =1-H19 -> 0.19145326 | J19: =tabla_mortalidad_hombre_2010!D17 -> 2.5 | K19: =tabla_mortalidad_hombre_2010!K17 -> 12.324894 | L19: =H19^F19 -> 0.81248796 | M19: =1-L19 -> 0.18751204 | N19: =N18*L18 -> 60975.739 | O19: =N19*M19 -> 11433.685 | P19: =(((-5/24)*O18)+((2.5)*O19)+((5/24)*O20))/O19 -> 2.568481 | Q19: =(C19*N20)+(P19*O19) -> 277077.47 | R19: =R20+Q19 -> 791265.12 | S19: =R19/N19 -> 12.976721 | T19: =S19-K19 -> 0.65182688
B20: 75 | C20: 5 | D20: ='Defunciones generales'!D18 -> 1136 | E20: =Homicidios!N23 -> 12.134019 | F20: =(D20-E20)/D20 -> 0.98931865 | G20: =tabla_mortalidad_hombre_2010!G18 -> 39027.394 | H20: =tabla_mortalidad_hombre_2010!F18 -> 0.71506445 | I20: =1-H20 -> 0.28493555 | J20: =tabla_mortalidad_hombre_2010!D18 -> 2.5 | K20: =tabla_mortalidad_hombre_2010!K18 -> 9.6512997 | L20: =H20^F20 -> 0.71763065 | M20: =1-L20 -> 0.28236935 | N20: =N19*L19 -> 49542.054 | O20: =N20*M20 -> 13989.157 | P20: =(((-5/24)*O19)+((2.5)*O20)+((5/24)*O21))/O20 -> 2.5378324 | Q20: =(C20*N21)+(P20*O20) -> 213266.62 | R20: =R21+Q20 -> 514187.65 | S20: =R20/N20 -> 10.378812 | T20: =S20-K20 -> 0.72751211
B21: 80 | C21: 5 | D21: ='Defunciones generales'!D19 -> 958 | E21: =Homicidios!N24 -> 4.0446729 | F21: =(D21-E21)/D21 -> 0.995778 | G21: =tabla_mortalidad_hombre_2010!G19 -> 27907.102 | H21: =tabla_mortalidad_hombre_2010!F19 -> 0.60566674 | I21: =1-H21 -> 0.39433326 | J21: =tabla_mortalidad_hombre_2010!D19 -> 2.5 | K21: =tabla_mortalidad_hombre_2010!K19 -> 7.5009163 | L21: =H21^F21 -> 0.6069503 | M21: =1-L21 -> 0.3930497 | N21: =N20*L20 -> 35552.896 | O21: =N21*M21 -> 13974.055 | P21: =C21+(F21*(I21/M21)*(J21-C21)) -> 2.5024253 | Q21: =(C21*N22)+(P21*O21) -> 142863.23 | R21: =R22+Q21 -> 300921.03 | S21: =R21/N21 -> 8.4640371 | T21: =S21-K21 -> 0.96312088
B22: 85 | C22: 5 | D22: ='Defunciones generales'!D20 -> 1136 | E22: =Homicidios!N25 -> 16.178692 | F22: =(D22-E22)/D22 -> 0.98575819 | G22: =tabla_mortalidad_hombre_2010!G20 -> 16902.403 | H22: =tabla_mortalidad_hombre_2010!F20 -> 0 | I22: =1-H22 -> 1 | J22: =tabla_mortalidad_hombre_2010!D20 -> 0 | K22: =tabla_mortalidad_hombre_2010!K20 -> 5.7568779 | L22: =H22^F22 -> 0 | M22: =1-L22 -> 1 | N22: =N21*L21 -> 21578.841 | O22: =N22*M22 -> 21578.841 | P22: =K22/F22 -> 5.8400507 | Q22: =N22/[1]LT!E39 -> 158057.8 | R22: =Q22 -> 158057.8 | S22: =R22/N22 -> 7.3246658 | T22: =S22-K22 -> 1.567788
B24: Mujeres, 2019
B26: Age x | C26: n | D26: nDx | E26: nDxi | I26: nqx | K26: e0 | M26: nqx_i | O26: ndx_i | Q26: L | R26: T | S26: e0_i | T26: diff | AA26: Hombres | AB26: Mujeres
B27: 0 | C27: 1 | D27: ='Defunciones generales'!D59 -> 397 | E27: =Homicidios!N64 -> 2.0070299 | F27: =(D27-E27)/D27 -> 0.99494451 | G27: =tabla_mortalidad_mujer_2010!G2 -> 100000 | H27: =tabla_mortalidad_mujer_2010!F2 -> 0.98681623 | I27: =1-H27 -> 0.01318377 | J27: =tabla_mortalidad_mujer_2010!D2 -> 0.090362626 | K27: =tabla_mortalidad_mujer_2010!K2 -> 75.078613 | L27: =H27^F27 -> 0.98688244 | M27: =1-L27 -> 0.013117559 | N27: 100000 | O27: =N27*M27 -> 1311.7559 | P27: =C27+(F27*(I27/M27)*(J27-C27)) -> 0.090393074 | Q27: =(C27*N28)+(P27*O27) -> 98806.818 | R27: =R28+Q27 -> 7658202.4 | S27: =R27/N27 -> 76.582024 | T27: =S27-K27 -> 1.5034114 | Z27: Sin homicidios | AA27: =S4 -> 70.676068 | AB27: =S27 -> 76.582024
B28: 1 | C28: 4 | D28: ='Defunciones generales'!D60 -> 75 | E28: =Homicidios!N65 -> 5.0175747 | F28: =(D28-E28)/D28 -> 0.933099 | G28: =tabla_mortalidad_mujer_2010!G3 -> 98681.623 | H28: =tabla_mortalidad_mujer_2010!F3 -> 0.997767 | I28: =1-H28 -> 0.0022330014 | J28: =tabla_mortalidad_mujer_2010!D3 -> 1.5017441 | K28: =tabla_mortalidad_mujer_2010!K3 -> 75.080449 | L28: =H28^F28 -> 0.99791623 | M28: =1-L28 -> 0.0020837671 | N28: =N27*L27 -> 98688.244 | O28: =N28*M28 -> 205.64332 | P28: =C28+(F28*(I28/M28)*(J28-C28)) -> 1.5019309 | Q28: =(C28*N29)+(P28*O28) -> 394239.27 | R28: =R29+Q28 -> 7559395.6 | S28: =R28/N28 -> 76.598745 | T28: =S28-K28 -> 1.518296 | V28: Número de años que se espera que viva una mujer de 0 años hasta llegar a los 85 años. | Z28: Con homicidios | AA28: =K4 -> 62.494617 | AB28: =K27 -> 75.078613
B29: 5 | C29: 5 | D29: ='Defunciones generales'!D61 -> 41 | E29: =Homicidios!N66 -> 6.0210896 | F29: =(D29-E29)/D29 -> 0.85314416 | G29: =tabla_mortalidad_mujer_2010!G4 -> 98461.267 | H29: =tabla_mortalidad_mujer_2010!F4 -> 0.9987923 | I29: =1-H29 -> 0.0012077003 | J29: =tabla_mortalidad_mujer_2010!D4 -> 2.5 | K29: =tabla_mortalidad_mujer_2010!K4 -> 71.245118 | L29: =H29^F29 -> 0.99896957 | M29: =1-L29 -> 0.0010304339 | N29: =N28*L28 -> 98482.601 | O29: =N29*M29 -> 101.47981 | P29: =C29+(F29*(I29/M29)*(J29-C29)) -> 2.5002218 | Q29: =(C29*N30)+(P29*O29) -> 492159.33 | R29: =R30+Q29 -> 7165156.3 | S29: =R29/N29 -> 72.755556 | T29: =S29-K29 -> 1.510438 | AA29: =AA27-AA28 -> 8.1814516 | AB29: =AB27-AB28 -> 1.5034114
B30: 10 | C30: 5 | D30: ='Defunciones generales'!D62 -> 57 | E30: =Homicidios!N67 -> 16.056239 | F30: =(D30-E30)/D30 -> 0.7183116 | G30: =tabla_mortalidad_mujer_2010!G5 -> 98342.355 | H30: =tabla_mortalidad_mujer_2010!F5 -> 0.99827307 | I30: =1-H30 -> 0.0017269276 | J30: =tabla_mortalidad_mujer_2010!D5 -> 2.5 | K30: =tabla_mortalidad_mujer_2010!K5 -> 66.328241 | L30: =H30^F30 -> 0.99875923 | M30: =1-L30 -> 0.001240774 | N30: =N29*L29 -> 98381.121 | O30: =N30*M30 -> 122.06874 | P30: =(((-5/24)*O29)+((2.5)*O30)+((5/24)*O31))/O30 -> 2.9513773 | Q30: =(C30*N31)+(P30*O30) -> 491655.53 | R30: =R31+Q30 -> 6672997 | S30: =R30/N30 -> 67.828024 | T30: =S30-K30 -> 1.4997822
B31: 15 | C31: 5 | D31: ='Defunciones generales'!D63 -> 192 | E31: =Homicidios!N68 -> 69.242531 | F31: =(D31-E31)/D31 -> 0.63936182 | G31: =tabla_mortalidad_mujer_2010!G6 -> 98172.525 | H31: =tabla_mortalidad_mujer_2010!F6 -> 0.99418095 | I31: =1-H31 -> 0.0058190499 | J31: =tabla_mortalidad_mujer_2010!D6 -> 2.5 | K31: =tabla_mortalidad_mujer_2010!K6 -> 61.438659 | L31: =H31^F31 -> 0.99627561 | M31: =1-L31 -> 0.0037243925 | N31: =N30*L30 -> 98259.052 | O31: =N31*M31 -> 365.95528 | P31: =(((-5/24)*O30)+((2.5)*O31)+((5/24)*O32))/O31 -> 2.6392868 | Q31: =(C31*N32)+(P31*O31) -> 490431.35 | R31: =R32+Q31 -> 6181341.5 | S31: =R31/N31 -> 62.908621 | T31: =S31-K31 -> 1.469962 | V31: Sin COVID | W31: Con COVID
B32: 20 | C32: 5 | D32: ='Defunciones generales'!D64 -> 207 | E32: =Homicidios!N69 -> 96.337434 | F32: =(D32-E32)/D32 -> 0.53460177 | G32: =tabla_mortalidad_mujer_2010!G7 -> 97601.254 | H32: =tabla_mortalidad_mujer_2010!F7 -> 0.99300376 | I32: =1-H32 -> 0.0069962354 | J32: =tabla_mortalidad_mujer_2010!D7 -> 2.5 | K32: =tabla_mortalidad_mujer_2010!K7 -> 56.783633 | L32: =H32^F32 -> 0.99625369 | M32: =1-L32 -> 0.0037463098 | N32: =N31*L31 -> 97893.097 | O32: =N32*M32 -> 366.73787 | P32: =(((-5/24)*O31)+((2.5)*O32)+((5/24)*O33))/O32 -> 2.5058951 | Q32: =(C32*N33)+(P32*O32) -> 488550.8 | R32: =R33+Q32 -> 5690910.1 | S32: =R32/N32 -> 58.133927 | T32: =S32-K32 -> 1.3502934 | V32: =([2]TV!M29-[2]TV!M47)/[2]TV!J29 -> 73.3257 | W32: =(R27-R45)/N27 -> 74.125438
B33: 25 | C33: 5 | D33: ='Defunciones generales'!D65 -> 204 | E33: =Homicidios!N70 -> 101.35501 | F33: =(D33-E33)/D33 -> 0.50316172 | G33: =tabla_mortalidad_mujer_2010!G8 -> 96918.413 | H33: =tabla_mortalidad_mujer_2010!F8 -> 0.99234555 | I33: =1-H33 -> 0.0076544521 | J33: =tabla_mortalidad_mujer_2010!D8 -> 2.5 | K33: =tabla_mortalidad_mujer_2010!K8 -> 52.16609 | L33: =H33^F33 -> 0.99614122 | M33: =1-L33 -> 0.003858779 | N33: =N32*L32 -> 97526.359 | O33: =N33*M33 -> 376.33266 | P33: =(((-5/24)*O32)+((2.5)*O33)+((5/24)*O34))/O33 -> 2.5907049 | Q33: =(C33*N34)+(P33*O33) -> 486725.1 | R33: =R34+Q33 -> 5202359.3 | S33: =R33/N33 -> 53.34311 | T33: =S33-K33 -> 1.1770201 | V33: Diff | W33: =W32-V32 -> 0.79973789
B34: 30 | C34: 5 | D34: ='Defunciones generales'!D66 -> 237 | E34: =Homicidios!N71 -> 93.326889 | F34: =(D34-E34)/D34 -> 0.60621566 | G34: =tabla_mortalidad_mujer_2010!G9 -> 96176.555 | H34: =tabla_mortalidad_mujer_2010!F9 -> 0.99100679 | I34: =1-H34 -> 0.0089932134 | J34: =tabla_mortalidad_mujer_2010!D9 -> 2.5 | K34: =tabla_mortalidad_mujer_2010!K9 -> 47.549189 | L34: =H34^F34 -> 0.99453848 | M34: =1-L34 -> 0.0054615208 | N34: =N33*L33 -> 97150.026 | O34: =N34*M34 -> 530.58689 | P34: =(((-5/24)*O33)+((2.5)*O34)+((5/24)*O35))/O34 -> 2.5904326 | Q34: =(C34*N35)+(P34*O34) -> 484471.65 | R34: =R35+Q34 -> 4715634.2 | S34: =R34/N34 -> 48.539711 | T34: =S34-K34 -> 0.99052191
B35: 35 | C35: 5 | D35: ='Defunciones generales'!D67 -> 222 | E35: =Homicidios!N72 -> 51.179262 | F35: =(D35-E35)/D35 -> 0.76946278 | G35: =tabla_mortalidad_mujer_2010!G10 -> 95311.619 | H35: =tabla_mortalidad_mujer_2010!F10 -> 0.99184779 | I35: =1-H35 -> 0.0081522097 | J35: =tabla_mortalidad_mujer_2010!D10 -> 2.5 | K35: =tabla_mortalidad_mujer_2010!K10 -> 42.958003 | L35: =H35^F35 -> 0.99372126 | M35: =1-L35 -> 0.0062787363 | N35: =N34*L34 -> 96619.44 | O35: =N35*M35 -> 606.64799 | P35: =(((-5/24)*O34)+((2.5)*O35)+((5/24)*O36))/O35 -> 2.6207201 | Q35: =(C35*N36)+(P35*O35) -> 481653.81 | R35: =R36+Q35 -> 4231162.6 | S35: =R35/N35 -> 43.792042 | T35: =S35-K35 -> 0.83403944
B36: 40 | C36: 5 | D36: ='Defunciones generales'!D68 -> 261 | E36: =Homicidios!N73 -> 46.161687 | F36: =(D36-E36)/D36 -> 0.8231353 | G36: =tabla_mortalidad_mujer_2010!G11 -> 94534.619 | H36: =tabla_mortalidad_mujer_2010!F11 -> 0.98884951 | I36: =1-H36 -> 0.01115049 | J36: =tabla_mortalidad_mujer_2010!D11 -> 2.5 | K36: =tabla_mortalidad_mujer_2010!K11 -> 38.290536 | L36: =H36^F36 -> 0.99081255 | M36: =1-L36 -> 0.009187452 | N36: =N35*L35 -> 96012.792 | O36: =N36*M36 -> 882.11291 | P36: =(((-5/24)*O35)+((2.5)*O36)+((5/24)*O37))/O36 -> 2.692775 | Q36: =(C36*N37)+(P36*O36) -> 478028.72 | R36: =R37+Q36 -> 3749508.8 | S36: =R36/N36 -> 39.052179 | T36: =S36-K36 -> 0.76164365
B37: 45 | C37: 5 | D37: ='Defunciones generales'!D69 -> 327 | E37: =Homicidios!N74 -> 35.123023 | F37: =(D37-E37)/D37 -> 0.89259014 | G37: =tabla_mortalidad_mujer_2010!G12 -> 93480.512 | H37: =tabla_mortalidad_mujer_2010!F12 -> 0.98325812 | I37: =1-H37 -> 0.016741882 | J37: =tabla_mortalidad_mujer_2010!D12 -> 2.5 | K37: =tabla_mortalidad_mujer_2010!K12 -> 33.694118 | L37: =H37^F37 -> 0.98504284 | M37: =1-L37 -> 0.014957158 | N37: =N36*L36 -> 95130.679 | O37: =N37*M37 -> 1422.8846 | P37: =(((-5/24)*O36)+((2.5)*O37)+((5/24)*O38))/O37 -> 2.6985261 | Q37: =(C37*N38)+(P37*O37) -> 472378.66 | R37: =R38+Q37 -> 3271480 | S37: =R37/N37 -> 34.389327 | T37: =S37-K37 -> 0.69520932
B38: 50 | C38: 5 | D38: ='Defunciones generales'!D70 -> 405 | E38: =Homicidios!N75 -> 20.070299 | F38: =(D38-E38)/D38 -> 0.95044371 | G38: =tabla_mortalidad_mujer_2010!G13 -> 91915.472 | H38: =tabla_mortalidad_mujer_2010!F13 -> 0.97488759 | I38: =1-H38 -> 0.025112414 | J38: =tabla_mortalidad_mujer_2010!D13 -> 2.5 | K38: =tabla_mortalidad_mujer_2010!K13 -> 29.225258 | L38: =H38^F38 -> 0.97611708 | M38: =1-L38 -> 0.023882919 | N38: =N37*L37 -> 93707.794 | O38: =N38*M38 -> 2238.0157 | P38: =(((-5/24)*O37)+((2.5)*O38)+((5/24)*O39))/O38 -> 2.7144794 | Q38: =(C38*N39)+(P38*O38) -> 463423.94 | R38: =R39+Q38 -> 2799101.4 | S38: =R38/N38 -> 29.870529 | T38: =S38-K38 -> 0.64527054
B39: 55 | C39: 5 | D39: ='Defunciones generales'!D71 -> 493 | E39: =Homicidios!N76 -> 9.0316344 | F39: =(D39-E39)/D39 -> 0.98168025 | G39: =tabla_mortalidad_mujer_2010!G14 -> 89607.253 | H39: =tabla_mortalidad_mujer_2010!F14 -> 0.95851076 | I39: =1-H39 -> 0.041489239 | J39: =tabla_mortalidad_mujer_2010!D14 -> 2.5 | K39: =tabla_mortalidad_mujer_2010!K14 -> 24.913682 | L39: =H39^F39 -> 0.95925513 | M39: =1-L39 -> 0.040744868 | N39: =N38*L38 -> 91469.778 | O39: =N39*M39 -> 3726.924 | P39: =(((-5/24)*O38)+((2.5)*O39)+((5/24)*O40))/O39 -> 2.6867211 | Q39: =(C39*N40)+(P39*O39) -> 448727.48 | R39: =R40+Q39 -> 2335677.4 | S39: =R39/N39 -> 25.534963 | T39: =S39-K39 -> 0.62128119
B40: 60 | C40: 5 | D40: ='Defunciones generales'!D72 -> 645 | E40: =Homicidios!N77 -> 7.0246046 | F40: =(D40-E40)/D40 -> 0.98910914 | G40: =tabla_mortalidad_mujer_2010!G15 -> 85889.516 | H40: =tabla_mortalidad_mujer_2010!F15 -> 0.93574726 | I40: =1-H40 -> 0.064252736 | J40: =tabla_mortalidad_mujer_2010!D15 -> 2.5 | K40: =tabla_mortalidad_mujer_2010!K15 -> 20.883861 | L40: =H40^F40 -> 0.9364243 | M40: =1-L40 -> 0.063575702 | N40: =N39*L39 -> 87742.854 | O40: =N40*M40 -> 5578.3136 | P40: =(((-5/24)*O39)+((2.5)*O40)+((5/24)*O41))/O40 -> 2.6572377 | Q40: =(C40*N41)+(P40*O40) -> 425645.61 | R40: =R41+Q40 -> 1886950 | S40: =R40/N40 -> 21.505455 | T40: =S40-K40 -> 0.62159375
B41: 65 | C41: 5 | D41: ='Defunciones generales'!D73 -> 762 | E41: =Homicidios!N78 -> 7.0246046 | F41: =(D41-E41)/D41 -> 0.99078136 | G41: =tabla_mortalidad_mujer_2010!G16 -> 80370.879 | H41: =tabla_mortalidad_mujer_2010!F16 -> 0.90254635 | I41: =1-H41 -> 0.097453647 | J41: =tabla_mortalidad_mujer_2010!D16 -> 2.5 | K41: =tabla_mortalidad_mujer_2010!K16 -> 17.146182 | L41: =H41^F41 -> 0.90339988 | M41: =1-L41 -> 0.096600125 | N41: =N40*L40 -> 82164.541 | O41: =N41*M41 -> 7937.1049 | P41: =(((-5/24)*O40)+((2.5)*O41)+((5/24)*O42))/O41 -> 2.6475987 | Q41: =(C41*N42)+(P41*O41) -> 392151.45 | R41: =R42+Q41 -> 1461304.4 | S41: =R41/N41 -> 17.785097 | T41: =S41-K41 -> 0.63891563
B42: 70 | C42: 5 | D42: ='Defunciones generales'!D74 -> 952 | E42: =Homicidios!N79 -> 3.0105448 | F42: =(D42-E42)/D42 -> 0.99683766 | G42: =tabla_mortalidad_mujer_2010!G17 -> 72538.444 | H42: =tabla_mortalidad_mujer_2010!F17 -> 0.84865104 | I42: =1-H42 -> 0.15134896 | J42: =tabla_mortalidad_mujer_2010!D17 -> 2.5 | K42: =tabla_mortalidad_mujer_2010!K17 -> 13.727623 | L42: =H42^F42 -> 0.84909157 | M42: =1-L42 -> 0.15090843 | N42: =N41*L41 -> 74227.436 | O42: =N42*M42 -> 11201.546 | P42: =(((-5/24)*O41)+((2.5)*O42)+((5/24)*O43))/O42 -> 2.6264288 | Q42: =(C42*N43)+(P42*O42) -> 344549.51 | R42: =R43+Q42 -> 1069152.9 | S42: =R42/N42 -> 14.403743 | T42: =S42-K42 -> 0.67612024
B43: 75 | C43: 5 | D43: ='Defunciones generales'!D75 -> 978 | E43: =Homicidios!N80 -> 2.0070299 | F43: =(D43-E43)/D43 -> 0.99794782 | G43: =tabla_mortalidad_mujer_2010!G18 -> 61559.826 | H43: =tabla_mortalidad_mujer_2010!F18 -> 0.76579001 | I43: =1-H43 -> 0.23420999 | J43: =tabla_mortalidad_mujer_2010!D18 -> 2.5 | K43: =tabla_mortalidad_mujer_2010!K18 -> 10.729964 | L43: =H43^F43 -> 0.76620948 | M43: =1-L43 -> 0.23379052 | N43: =N42*L42 -> 63025.89 | O43: =N43*M43 -> 14734.856 | P43: =(((-5/24)*O42)+((2.5)*O43)+((5/24)*O44))/O43 -> 2.5790173 | Q43: =(C43*N44)+(P43*O43) -> 279456.62 | R43: =R44+Q43 -> 724603.39 | S43: =R43/N43 -> 11.496916 | T43: =S43-K43 -> 0.76695243
...

Sheet DM_2021
B2: Hombres, 2019
B3: Age x | C3: n | D3: nDx | E3: nDxi | I3: nqx | K3: e0 | M3: nqx_i | O3: ndx_i | Q3: L | R3: T | S3: e0_i | T3: diff
B4: 0 | C4: 1 | D4: ='Defunciones generales'!D40 -> 418 | E4: =Homicidios!N45 -> 1.0551918 | F4: =(D4-E4)/D4 -> 0.99747562 | G4: =tabla_mortalidad_hombre_2021!G2 -> 100000 | H4: =tabla_mortalidad_hombre_2021!F2 -> 0.98336741 | I4: =1-H4 -> 0.016632594 | J4: =tabla_mortalidad_hombre_2021!D2 -> 0.090327701 | K4: =tabla_mortalidad_hombre_2021!K2 -> 66.491437 | L4: =H4^F4 -> 0.98340904 | M4: =1-L4 -> 0.016590957 | N4: 100000 | O4: =N4*M4 -> 1659.0957 | P4: =C4+(F4*(I4/M4)*(J4-C4)) -> 0.090346905 | Q4: =(C4*N5)+(P4*O4) -> 98490.798 | R4: =R5+Q4 -> 6965210.5 | S4: =R4/N4 -> 69.652105 | T4: =S4-K4 -> 3.1606682
B5: 1 | C5: 4 | D5: ='Defunciones generales'!D41 -> 101 | E5: =Homicidios!N46 -> 2.1103835 | F5: =(D5-E5)/D5 -> 0.97910511 | G5: =tabla_mortalidad_hombre_2021!G3 -> 98336.741 | H5: =tabla_mortalidad_hombre_2021!F3 -> 0.99665705 | I5: =1-H5 -> 0.003342951 | J5: =tabla_mortalidad_hombre_2021!D3 -> 1.6034431 | K5: =tabla_mortalidad_hombre_2021!K3 -> 66.61454 | L5: =H5^F5 -> 0.99672679 | M5: =1-L5 -> 0.0032732149 | N5: =N4*L4 -> 98340.904 | O5: =N5*M5 -> 321.89091 | P5: =C5+(F5*(I5/M5)*(J5-C5)) -> 1.6035269 | Q5: =(C5*N6)+(P5*O5) -> 392592.21 | R5: =R6+Q5 -> 6866719.7 | S5: =R5/N5 -> 69.825672 | T5: =S5-K5 -> 3.2111321 | V5: Número de años que se espera que viva un hombre de 0 años hasta llegar a los 85 años.
B6: 5 | C6: 5 | D6: ='Defunciones generales'!D42 -> 44 | E6: =Homicidios!N47 -> 3.1655753 | F6: =(D6-E6)/D6 -> 0.92805511 | G6: =tabla_mortalidad_hombre_2021!G4 -> 98008.006 | H6: =tabla_mortalidad_hombre_2021!F4 -> 0.99850112 | I6: =1-H6 -> 0.0014988758 | J6: =tabla_mortalidad_hombre_2021!D4 -> 2.5 | K6: =tabla_mortalidad_hombre_2021!K4 -> 62.832598 | L6: =H6^F6 -> 0.99860889 | M6: =1-L6 -> 0.0013911144 | N6: =N5*L5 -> 98019.013 | O6: =N6*M6 -> 136.35566 | P6: =C6+(F6*(I6/M6)*(J6-C6)) -> 2.5001349 | Q6: =(C6*N7)+(P6*O6) -> 489754.2 | R6: =R7+Q6 -> 6474127.5 | S6: =R6/N6 -> 66.049711 | T6: =S6-K6 -> 3.2171133
B7: 10 | C7: 5 | D7: ='Defunciones generales'!D43 -> 89 | E7: =Homicidios!N48 -> 8.4415341 | F7: =(D7-E7)/D7 -> 0.9051513 | G7: =tabla_mortalidad_hombre_2021!G5 -> 97861.104 | H7: =tabla_mortalidad_hombre_2021!F5 -> 0.99738527 | I7: =1-H7 -> 0.0026147321 | J7: =tabla_mortalidad_hombre_2021!D5 -> 2.5 | K7: =tabla_mortalidad_hombre_2021!K5 -> 57.923165 | L7: =H7^F7 -> 0.99763298 | M7: =1-L7 -> 0.0023670219 | N7: =N6*L6 -> 97882.658 | O7: =N7*M7 -> 231.6904 | P7: =(((-5/24)*O6)+((2.5)*O7)+((5/24)*O8))/O7 -> 2.923976 | Q7: =(C7*N8)+(P7*O7) -> 488932.29 | R7: =R8+Q7 -> 5984373.3 | S7: =R7/N7 -> 61.138239 | T7: =S7-K7 -> 3.2150744
B8: 15 | C8: 5 | D8: ='Defunciones generales'!D44 -> 371 | E8: =Homicidios!N49 -> 163.55472 | F8: =(D8-E8)/D8 -> 0.55915169 | G8: =tabla_mortalidad_hombre_2021!G6 -> 97605.223 | H8: =tabla_mortalidad_hombre_2021!F6 -> 0.98889461 | I8: =1-H8 -> 0.011105386 | J8: =tabla_mortalidad_hombre_2021!D6 -> 2.5 | K8: =tabla_mortalidad_hombre_2021!K6 -> 53.068461 | L8: =H8^F8 -> 0.99377512 | M8: =1-L8 -> 0.0062248773 | N8: =N7*L7 -> 97650.967 | O8: =N8*M8 -> 607.86529 | P8: =(((-5/24)*O7)+((2.5)*O8)+((5/24)*O9))/O8 -> 2.6927006 | Q8: =(C8*N9)+(P8*O8) -> 486852.31 | R8: =R9+Q8 -> 5495441 | S8: =R8/N8 -> 56.27636 | T8: =S8-K8 -> 3.2078991 | V8: Sin COVID | W8: Con COVID
B9: 20 | C9: 5 | D9: ='Defunciones generales'!D45 -> 601 | E9: =Homicidios!N50 -> 339.77175 | F9: =(D9-E9)/D9 -> 0.43465599 | G9: =tabla_mortalidad_hombre_2021!G7 -> 96521.28 | H9: =tabla_mortalidad_hombre_2021!F7 -> 0.98127749 | I9: =1-H9 -> 0.018722513 | J9: =tabla_mortalidad_hombre_2021!D7 -> 2.5 | K9: =tabla_mortalidad_hombre_2021!K7 -> 48.63635 | L9: =H9^F9 -> 0.99181865 | M9: =1-L9 -> 0.0081813463 | N9: =N8*L8 -> 97043.102 | O9: =N9*M9 -> 793.94322 | P9: =(((-5/24)*O8)+((2.5)*O9)+((5/24)*O10))/O9 -> 2.6348259 | Q9: =(C9*N10)+(P9*O9) -> 483337.7 | R9: =R10+Q9 -> 5008588.7 | S9: =R9/N9 -> 51.612001 | T9: =S9-K9 -> 2.9756513 | V9: =([2]TV!M53-[2]TV!M71)/[2]TV!J53 -> 66.401396 | W9: =(R4-R22)/N4 -> 68.267477
B10: 25 | C10: 5 | D10: ='Defunciones generales'!D46 -> 731 | E10: =Homicidios!N51 -> 377.75865 | F10: =(D10-E10)/D10 -> 0.4832303 | G10: =tabla_mortalidad_hombre_2021!G8 -> 94714.159 | H10: =tabla_mortalidad_hombre_2021!F8 -> 0.9760336 | I10: =1-H10 -> 0.023966398 | J10: =tabla_mortalidad_hombre_2021!D8 -> 2.5 | K10: =tabla_mortalidad_hombre_2021!K8 -> 44.516619 | L10: =H10^F10 -> 0.98834611 | M10: =1-L10 -> 0.01165389 | N10: =N9*L9 -> 96249.159 | O10: =N10*M10 -> 1121.6771 | P10: =(((-5/24)*O9)+((2.5)*O10)+((5/24)*O11))/O10 -> 2.5952929 | Q10: =(C10*N11)+(P10*O10) -> 478548.49 | R10: =R11+Q10 -> 4525251 | S10: =R10/N10 -> 47.016006 | T10: =S10-K10 -> 2.4993866 | V10: Diff | W10: =W9-V9 -> 1.8660801
B11: 30 | C11: 5 | D11: ='Defunciones generales'!D47 -> 741 | E11: =Homicidios!N52 -> 361.93078 | F11: =(D11-E11)/D11 -> 0.5115644 | G11: =tabla_mortalidad_hombre_2021!G9 -> 92444.202 | H11: =tabla_mortalidad_hombre_2021!F9 -> 0.97331837 | I11: =1-H11 -> 0.026681627 | J11: =tabla_mortalidad_hombre_2021!D9 -> 2.5 | K11: =tabla_mortalidad_hombre_2021!K9 -> 40.548333 | L11: =H11^F11 -> 0.98626049 | M11: =1-L11 -> 0.013739509 | N11: =N10*L10 -> 95127.482 | O11: =N11*M11 -> 1307.0049 | P11: =(((-5/24)*O10)+((2.5)*O11)+((5/24)*O12))/O11 -> 2.5922695 | Q11: =(C11*N12)+(P11*O11) -> 472490.49 | R11: =R12+Q11 -> 4046702.5 | S11: =R11/N11 -> 42.539784 | T11: =S11-K11 -> 1.9914512
B12: 35 | C12: 5 | D12: ='Defunciones generales'!D48 -> 784 | E12: =Homicidios!N53 -> 306.00561 | F12: =(D12-E12)/D12 -> 0.60968672 | G12: =tabla_mortalidad_hombre_2021!G10 -> 89977.64 | H12: =tabla_mortalidad_hombre_2021!F10 -> 0.97044369 | I12: =1-H12 -> 0.029556306 | J12: =tabla_mortalidad_hombre_2021!D10 -> 2.5 | K12: =tabla_mortalidad_hombre_2021!K10 -> 36.591354 | L12: =H12^F12 -> 0.98187452 | M12: =1-L12 -> 0.018125478 | N12: =N11*L11 -> 93820.477 | O12: =N12*M12 -> 1700.541 | P12: =(((-5/24)*O11)+((2.5)*O12)+((5/24)*O13))/O12 -> 2.5965435 | Q12: =(C12*N13)+(P12*O12) -> 465015.21 | R12: =R13+Q12 -> 3574212 | S12: =R12/N12 -> 38.096289 | T12: =S12-K12 -> 1.5049356
B13: 40 | C13: 5 | D13: ='Defunciones generales'!D49 -> 839 | E13: =Homicidios!N54 -> 258.52198 | F13: =(D13-E13)/D13 -> 0.69186891 | G13: =tabla_mortalidad_hombre_2021!G11 -> 87318.233 | H13: =tabla_mortalidad_hombre_2021!F11 -> 0.96729587 | I13: =1-H13 -> 0.032704135 | J13: =tabla_mortalidad_hombre_2021!D11 -> 2.5 | K13: =tabla_mortalidad_hombre_2021!K11 -> 32.629657 | L13: =H13^F13 -> 0.97725736 | M13: =1-L13 -> 0.022742639 | N13: =N12*L12 -> 92119.936 | O13: =N13*M13 -> 2095.0504 | P13: =(((-5/24)*O12)+((2.5)*O13)+((5/24)*O14))/O13 -> 2.64625 | Q13: =(C13*N14)+(P13*O13) -> 455668.45 | R13: =R14+Q13 -> 3109196.8 | S13: =R13/N13 -> 33.751617 | T13: =S13-K13 -> 1.1219608
B14: 45 | C14: 5 | D14: ='Defunciones generales'!D50 -> 1101 | E14: =Homicidios!N55 -> 180.43779 | F14: =(D14-E14)/D14 -> 0.83611463 | G14: =tabla_mortalidad_hombre_2021!G12 -> 84462.566 | H14: =tabla_mortalidad_hombre_2021!F12 -> 0.9580156 | I14: =1-H14 -> 0.041984397 | J14: =tabla_mortalidad_hombre_2021!D12 -> 2.5 | K14: =tabla_mortalidad_hombre_2021!K12 -> 28.648336 | L14: =H14^F14 -> 0.96477345 | M14: =1-L14 -> 0.03522655 | N14: =N13*L13 -> 90024.885 | O14: =N14*M14 -> 3171.2661 | P14: =(((-5/24)*O13)+((2.5)*O14)+((5/24)*O15))/O14 -> 2.6578147 | Q14: =(C14*N15)+(P14*O14) -> 442696.73 | R14: =R15+Q14 -> 2653528.4 | S14: =R14/N14 -> 29.475499 | T14: =S14-K14 -> 0.82716252
B15: 50 | C15: 5 | D15: ='Defunciones generales'!D51 -> 1313 | E15: =Homicidios!N56 -> 108.68475 | F15: =(D15-E15)/D15 -> 0.9172241 | G15: =tabla_mortalidad_hombre_2021!G13 -> 80916.456 | H15: =tabla_mortalidad_hombre_2021!F13 -> 0.94368062 | I15: =1-H15 -> 0.056319385 | J15: =tabla_mortalidad_hombre_2021!D13 -> 2.5 | K15: =tabla_mortalidad_hombre_2021!K13 -> 24.794269 | L15: =H15^F15 -> 0.94821957 | M15: =1-L15 -> 0.05178043 | N15: =N14*L14 -> 86853.619 | O15: =N15*M15 -> 4497.3178 | P15: =(((-5/24)*O14)+((2.5)*O15)+((5/24)*O16))/O15 -> 2.6294822 | Q15: =(C15*N16)+(P15*O15) -> 423607.12 | R15: =R16+Q15 -> 2210831.6 | S15: =R15/N15 -> 25.454686 | T15: =S15-K15 -> 0.66041696
B16: 55 | C16: 5 | D16: ='Defunciones generales'!D52 -> 1407 | E16: =Homicidios!N57 -> 64.366698 | F16: =(D16-E16)/D16 -> 0.95425252 | G16: =tabla_mortalidad_hombre_2021!G14 -> 76359.291 | H16: =tabla_mortalidad_hombre_2021!F14 -> 0.92421549 | I16: =1-H16 -> 0.075784515 | J16: =tabla_mortalidad_hombre_2021!D14 -> 2.5 | K16: =tabla_mortalidad_hombre_2021!K14 -> 21.124804 | L16: =H16^F16 -> 0.92755363 | M16: =1-L16 -> 0.072446372 | N16: =N15*L15 -> 82356.301 | O16: =N16*M16 -> 5966.4152 | P16: =(((-5/24)*O15)+((2.5)*O16)+((5/24)*O17))/O16 -> 2.6388936 | Q16: =(C16*N17)+(P16*O16) -> 397694.17 | R16: =R17+Q16 -> 1787224.5 | S16: =R16/N16 -> 21.701126 | T16: =S16-K16 -> 0.57632263
B17: 60 | C17: 5 | D17: ='Defunciones generales'!D53 -> 1688 | E17: =Homicidios!N58 -> 32.710945 | F17: =(D17-E17)/D17 -> 0.98062148 | G17: =tabla_mortalidad_hombre_2021!G15 -> 70572.439 | H17: =tabla_mortalidad_hombre_2021!F15 -> 0.88699152 | I17: =1-H17 -> 0.11300848 | J17: =tabla_mortalidad_hombre_2021!D15 -> 2.5 | K17: =tabla_mortalidad_hombre_2021!K15 -> 17.652014 | L17: =H17^F17 -> 0.88905517 | M17: =1-L17 -> 0.11094483 | N17: =N16*L16 -> 76389.886 | O17: =N17*M17 -> 8475.0632 | P17: =(((-5/24)*O16)+((2.5)*O17)+((5/24)*O18))/O17 -> 2.6081404 | Q17: =(C17*N18)+(P17*O17) -> 361678.27 | R17: =R18+Q17 -> 1389530.3 | S17: =R17/N17 -> 18.189978 | T17: =S17-K17 -> 0.53796348
