Workbook

Sheet Chihuahua 2010
A1: Chihuahua: población total censada por sexo y grupos quinquenales de edad, 2000 | F1: Chihuahua: población total censada por sexo y grupos quinquenales de edad, 2010 | L1: Chihuahua: nacimientos por grupos quinquenales de edad de la madre, 2010
A3: Fecha de referencia: 06/12/2010 | F3: Fecha de referencia: 15/03/2020 | L3: Edad | M3: Chihuahua 2010 | N3: Población 30/06/2010 | P3: Chihuahua: nacimientos por sexo, 2010
L4: 15-19 | M4: 14662 | N4: =R17 -> 164495.41
A5: Edad | B5: Chihuahua 2010 | F5: Edad | G5: Chihuahua 2020 | L5: 20-24 | M5: 19720 | N5: =R23 -> 147419.16 | P5: Hombres | Q5: Mujeres | R5: Total
B6: Hombres | C6: Mujeres | D6: Total | G6: Hombres | H6: Mujeres | I6: Total | L6: 25-29 | M6: 15058 | N6: =R29 -> 132745.79 | P6: 33465 | Q6: 32313 | R6: =SUM(P6:Q6) -> 65778
A7: 0-4 | B7: 168769 | C7: 164023 | D7: =SUM(B7:C7) -> 332792 | F7: 0-4 | G7: 147914 | H7: 143968 | I7: =SUM(G7:H7) -> 291882 | L7: 30-34 | M7: 9635 | N7: =R35 -> 131173.54
A8: 5-9 | B8: 175855.92 | C8: 169713.29 | D8: =SUM(B8:C8) -> 345569.21 | F8: 5-9 | G8: 161514.21 | H8: 156457.05 | I8: =SUM(G8:H8) -> 317971.26 | L8: 35-39 | M8: 4748 | N8: =R41 -> 135604.44 | P8: K | Q8: =Q6/R6 -> 0.49124327
A9: 10-14 | B9: 169947.19 | C9: 164892.68 | D9: =SUM(B9:C9) -> 334839.87 | F9: 10-14 | G9: 169964.59 | H9: 164433.21 | I9: =SUM(G9:H9) -> 334397.8 | L9: 40-44 | M9: 1050 | N9: =R47 -> 116382.7
A10: 15-19 | B10: 167614.85 | C10: 164515.28 | D10: =SUM(B10:C10) -> 332130.13 | F10: 15-19 | G10: 166284.02 | H10: 160716.68 | I10: =SUM(G10:H10) -> 327000.7 | L10: 45-49 | M10: 130 | N10: =R53 -> 96841.767 | R10: =M11/R6 -> 0.98821795
A11: 20-24 | B11: 147463.48 | C11: 147370.41 | D11: =SUM(B11:C11) -> 294833.89 | F11: 20-24 | G11: 157605.17 | H11: 157104.36 | I11: =SUM(G11:H11) -> 314709.53 | L11: Total | M11: =SUM(M4:M10) -> 65003 | N11: =SUM(N4:N10) -> 924662.81
A12: 25-29 | B12: 130372.72 | C12: 132658.02 | D12: =SUM(B12:C12) -> 263030.74 | F12: 25-29 | G12: 148148.72 | H12: 150760.51 | I12: =SUM(G12:H12) -> 298909.22 | L12: Fuente: Elaborado sobre la base de estadísticas vitales
A13: 30-34 | B13: 128053.79 | C13: 131127.8 | D13: =SUM(B13:C13) -> 259181.59 | F13: 30-34 | G13: 135928.58 | H13: 140279.27 | I13: =SUM(G13:H13) -> 276207.85
A14: 35-39 | B14: 132500.81 | C14: 135616.38 | D14: =SUM(B14:C14) -> 268117.19 | F14: 35-39 | G14: 130881.2 | H14: 133327.18 | I14: =SUM(G14:H14) -> 264208.38 | K14: Tasas de crecimiento exponencial para Edades Específicas MEF
A15: 40-44 | B15: 113412.97 | C15: 116325.69 | D15: =SUM(B15:C15) -> 229738.66 | F15: 40-44 | G15: 124610.3 | H15: 127888.16 | I15: =SUM(G15:H15) -> 252498.46 | K15: 15-19
A16: 45-49 | B16: 92182.596 | C16: 96711.221 | D16: =SUM(B16:C16) -> 188893.82 | F16: 45-49 | G16: 123492 | H16: 125538.4 | I16: =SUM(G16:H16) -> 249030.4 | K16: Fechas | L16: ti | M16: N | N16: r | P16: ti | Q16: Δt | R16: N30/06/2010
A17: 50-54 | B17: 74259.377 | C17: 79481.796 | D17: =SUM(B17:C17) -> 153741.17 | F17: 50-54 | G17: 107825.78 | H17: 112554.08 | I17: =SUM(G17:H17) -> 220379.86 | K17: 40518 | L17: 2010.4495 | M17: =C10 -> 164515.28 | N17: =LN(M18/M17)/L19 -> -0.0023939213 | P17: =2010+6/12+0/365 -> 2010.5 | Q17: =P17-L17 -> 0.050456621 | R17: =M17*EXP($N$17*Q17) -> 164495.41
A18: 55-59 | B18: 53961.525 | C18: 58049.418 | D18: =SUM(B18:C18) -> 112010.94 | F18: 55-59 | G18: 84201.188 | H18: 89792.959 | I18: =SUM(G18:H18) -> 173994.15 | K18: 15/03/2020 | L18: 2020.2078 | M18: =H10 -> 160716.68
A19: 60-64 | B19: 43876.04 | C19: 48472.13 | D19: =SUM(B19:C19) -> 92348.17 | F19: 60-64 | G19: 66667.123 | H19: 74481.933 | I19: =SUM(G19:H19) -> 141149.06 | K19: Δt | L19: =L18-L17 -> 9.7582192
A20: 65-69 | B20: 33846.258 | C20: 37119.208 | D20: =SUM(B20:C20) -> 70965.466 | F20: 65-69 | G20: 47350.392 | H20: 53800.022 | I20: =SUM(G20:H20) -> 101150.41
A21: 70-74 | B21: 27101.97 | C21: 29022.647 | D21: =SUM(B21:C21) -> 56124.617 | F21: 70-74 | G21: 34257.462 | H21: 39911.879 | I21: =SUM(G21:H21) -> 74169.341 | K21: 20-24
A22: 75-79 | B22: 17065.999 | C22: 18397.714 | D22: =SUM(B22:C22) -> 35463.713 | F22: 75-79 | G22: 23521.38 | H22: 26846.402 | I22: =SUM(G22:H22) -> 50367.782 | K22: Fechas | L22: ti | M22: N | N22: r | P22: ti | Q22: Δt | R22: N30/06/2010
A23: 80-84 | B23: 9732.6947 | C23: 11619.989 | D23: =SUM(B23:C23) -> 21352.684 | F23: 80-84 | G23: 14302.418 | H23: 17148.751 | I23: =SUM(G23:H23) -> 31451.168 | K23: =K17 -> 40518 | L23: =L17 -> 2010.4495 | M23: =C11 -> 147370.41 | N23: =LN(M24/M23)/L25 -> 0.0065545844 | P23: =P17 -> 2010.5 | Q23: =P23-L23 -> 0.050456621 | R23: =M23*EXP($N$23*Q23) -> 147419.16
A24: 85-89 | B24: 6527.6621 | C24: 8802.8969 | D24: =SUM(B24:C24) -> 15330.559 | F24: 85-89 | G24: 9353.238 | H24: 13038.421 | I24: =SUM(G24:H24) -> 22391.66 | K24: =K18 -> 15/03/2020 | L24: =L18 -> 2020.2078 | M24: =H11 -> 157104.36
A25: Total | B25: =SUM(B7:B24) -> 1692544.8 | C25: =SUM(C7:C24) -> 1713919.6 | D25: =SUM(B25:C25) -> 3406464.4 | F25: Total | G25: =SUM(G7:G24) -> 1853821.8 | H25: =SUM(H7:H24) -> 1888047.3 | I25: =SUM(G25:H25) -> 3741869 | K25: Δt | L25: =L24-L23 -> 9.7582192
K27: 25-29
K28: Fechas | L28: ti | M28: N | N28: r | P28: ti | Q28: Δt | R28: N30/06/2010
A29: Tasas de crecimiento exponencial para el Total de la Población | K29: =K23 -> 40518 | L29: =L23 -> 2010.4495 | M29: =C12 -> 132658.02 | N29: =LN(M30/M29)/L31 -> 0.013108746 | P29: =P23 -> 2010.5 | Q29: =P29-L29 -> 0.050456621 | R29: =M29*EXP($N$29*Q29) -> 132745.79
K30: =K24 -> 15/03/2020 | L30: =L24 -> 2020.2078 | M30: =H12 -> 150760.51
A31: Fechas | B31: ti | C31: N | D31: r | F31: ti | G31: Δt | H31: N30/06/2010 | K31: Δt | L31: =L30-L29 -> 9.7582192
A32: 40518 | B32: 2010.4495 | C32: =D25 -> 3406464.4 | D32: =LN(C33/C32)/B34 -> 0.0096237129 | F32: =2010+6/12+0/365 -> 2010.5 | G32: =F32-B32 -> 0.050456621 | H32: =C32*EXP($D$32*G32) -> 3408118.9
A33: 15/03/2020 | B33: 2020.2078 | C33: =I25 -> 3741869 | K33: 30-34
A34: Δt | B34: =B33-B32 -> 9.7582192 | K34: Fechas | L34: ti | M34: N | N34: r | P34: ti | Q34: Δt | R34: N30/06/2010
K35: =K29 -> 40518 | L35: =L29 -> 2010.4495 | M35: =C13 -> 131127.8 | N35: =LN(M36/M35)/L37 -> 0.0069134349 | P35: =P29 -> 2010.5 | Q35: =P35-L35 -> 0.050456621 | R35: =M35*EXP($N$35*Q35) -> 131173.54
K36: =K30 -> 15/03/2020 | L36: =L30 -> 2020.2078 | M36: =H13 -> 140279.27
K37: Δt | L37: =L36-L35 -> 9.7582192
K39: 35-39
K40: Fechas | L40: ti | M40: N | N40: r | P40: ti | Q40: Δt | R40: N30/06/2010
K41: =K35 -> 40518 | L41: =L35 -> 2010.4495 | M41: =C14 -> 135616.38 | N41: =LN(M42/M41)/L43 -> -0.0017445841 | P41: =P35 -> 2010.5 | Q41: =P41-L41 -> 0.050456621 | R41: =M41*EXP($N$41*Q41) -> 135604.44
K42: =K36 -> 15/03/2020 | L42: =L36 -> 2020.2078 | M42: =H14 -> 133327.18
K43: Δt | L43: =L42-L41 -> 9.7582192
...

Sheet Chihuahua 2019
A1: Chihuahua: población total censada por sexo y grupos quinquenales de edad, 2010 | F1: Chihuahua: población total censada por sexo y grupos quinquenales de edad, 2020 | L1: Chihuahua: nacimientos por grupos quinquenales de edad de la madre, 2010
A3: Fecha de referencia: 06/12/2010 | F3: Fecha de referencia: 15/03/2020 | L3: Edad | M3: Chihuahua 2010 | N3: Población 30/06/2010 | P3: Chihuahua: nacimientos por sexo, 2010
L4: 15-19 | M4: 13227 | N4: =R17 -> 160989.22
A5: Edad | B5: Chihuahua 2010 | F5: Edad | G5: Chihuahua 2020 | L5: 20-24 | M5: 20308 | N5: =R23 -> 156377.23 | P5: Hombres | Q5: Mujeres | R5: Total
B6: Hombres | C6: Mujeres | D6: Total | G6: Hombres | H6: Mujeres | I6: Total | L6: 25-29 | M6: 18618 | N6: =R29 -> 149368.24 | P6: 34058 | Q6: 32841 | R6: 66899
A7: 0-4 | B7: 168769 | C7: 164023 | D7: =SUM(B7:C7) -> 332792 | F7: 0-4 | G7: 147914 | H7: 143968 | I7: =SUM(G7:H7) -> 291882 | L7: 30-34 | M7: 10132 | N7: =R35 -> 139594.55
A8: 5-9 | B8: 175855.92 | C8: 169713.29 | D8: =SUM(B8:C8) -> 345569.21 | F8: 5-9 | G8: 161514.21 | H8: 156457.05 | I8: =SUM(G8:H8) -> 317971.26 | L8: 35-39 | M8: 4453 | N8: =R41 -> 133491.91 | P8: K | Q8: =Q6/R6 -> 0.4909042
A9: 10-14 | B9: 169947.19 | C9: 164892.68 | D9: =SUM(B9:C9) -> 334839.87 | F9: 10-14 | G9: 169964.59 | H9: 164433.21 | I9: =SUM(G9:H9) -> 334397.8 | L9: 40-44 | M9: 918 | N9: =R47 -> 127012.18
A10: 15-19 | B10: 167614.85 | C10: 164515.28 | D10: =SUM(B10:C10) -> 332130.13 | F10: 15-19 | G10: 166284.02 | H10: 160716.68 | I10: =SUM(G10:H10) -> 327000.7 | L10: 45-49 | M10: 124 | N10: =R53 -> 123185.32
A11: 20-24 | B11: 147463.48 | C11: 147370.41 | D11: =SUM(B11:C11) -> 294833.89 | F11: 20-24 | G11: 157605.17 | H11: 157104.36 | I11: =SUM(G11:H11) -> 314709.53 | L11: Total | M11: =SUM(M4:M10) -> 67780 | N11: =SUM(N4:N10) -> 990018.64
A12: 25-29 | B12: 130372.72 | C12: 132658.02 | D12: =SUM(B12:C12) -> 263030.74 | F12: 25-29 | G12: 148148.72 | H12: 150760.51 | I12: =SUM(G12:H12) -> 298909.22 | L12: Fuente: Elaborado sobre la base de estadísticas vitales
A13: 30-34 | B13: 128053.79 | C13: 131127.8 | D13: =SUM(B13:C13) -> 259181.59 | F13: 30-34 | G13: 135928.58 | H13: 140279.27 | I13: =SUM(G13:H13) -> 276207.85
A14: 35-39 | B14: 132500.81 | C14: 135616.38 | D14: =SUM(B14:C14) -> 268117.19 | F14: 35-39 | G14: 130881.2 | H14: 133327.18 | I14: =SUM(G14:H14) -> 264208.38 | K14: Tasas de crecimiento exponencial para Edades Específicas MEF
A15: 40-44 | B15: 113412.97 | C15: 116325.69 | D15: =SUM(B15:C15) -> 229738.66 | F15: 40-44 | G15: 124610.3 | H15: 127888.16 | I15: =SUM(G15:H15) -> 252498.46 | K15: 15-19
A16: 45-49 | B16: 92182.596 | C16: 96711.221 | D16: =SUM(B16:C16) -> 188893.82 | F16: 45-49 | G16: 123492 | H16: 125538.4 | I16: =SUM(G16:H16) -> 249030.4 | K16: Fechas | L16: ti | M16: N | N16: r | P16: ti | Q16: Δt | R16: N30/06/2010
A17: 50-54 | B17: 74259.377 | C17: 79481.796 | D17: =SUM(B17:C17) -> 153741.17 | F17: 50-54 | G17: 107825.78 | H17: 112554.08 | I17: =SUM(G17:H17) -> 220379.86 | K17: 40518 | L17: 2010.4495 | M17: =C10 -> 164515.28 | N17: =LN(M18/M17)/L19 -> -0.0023939213 | P17: =2019+6/12+0/365 -> 2019.5 | Q17: =P17-L17 -> 9.0504566 | R17: =M17*EXP($N$17*Q17) -> 160989.22
A18: 55-59 | B18: 53961.525 | C18: 58049.418 | D18: =SUM(B18:C18) -> 112010.94 | F18: 55-59 | G18: 84201.188 | H18: 89792.959 | I18: =SUM(G18:H18) -> 173994.15 | K18: 15/03/2020 | L18: 2020.2078 | M18: =H10 -> 160716.68
A19: 60-64 | B19: 43876.04 | C19: 48472.13 | D19: =SUM(B19:C19) -> 92348.17 | F19: 60-64 | G19: 66667.123 | H19: 74481.933 | I19: =SUM(G19:H19) -> 141149.06 | K19: Δt | L19: =L18-L17 -> 9.7582192
A20: 65-69 | B20: 33846.258 | C20: 37119.208 | D20: =SUM(B20:C20) -> 70965.466 | F20: 65-69 | G20: 47350.392 | H20: 53800.022 | I20: =SUM(G20:H20) -> 101150.41
A21: 70-74 | B21: 27101.97 | C21: 29022.647 | D21: =SUM(B21:C21) -> 56124.617 | F21: 70-74 | G21: 34257.462 | H21: 39911.879 | I21: =SUM(G21:H21) -> 74169.341 | K21: 20-24
A22: 75-79 | B22: 17065.999 | C22: 18397.714 | D22: =SUM(B22:C22) -> 35463.713 | F22: 75-79 | G22: 23521.38 | H22: 26846.402 | I22: =SUM(G22:H22) -> 50367.782 | K22: Fechas | L22: ti | M22: N | N22: r | P22: ti | Q22: Δt | R22: N30/06/2010
A23: 80-84 | B23: 9732.6947 | C23: 11619.989 | D23: =SUM(B23:C23) -> 21352.684 | F23: 80-84 | G23: 14302.418 | H23: 17148.751 | I23: =SUM(G23:H23) -> 31451.168 | K23: =K17 -> 40518 | L23: =L17 -> 2010.4495 | M23: =C11 -> 147370.41 | N23: =LN(M24/M23)/L25 -> 0.0065545844 | P23: =P17 -> 2019.5 | Q23: =P23-L23 -> 9.0504566 | R23: =M23*EXP($N$23*Q23) -> 156377.23
A24: 85-89 | B24: 6527.6621 | C24: 8802.8969 | D24: =SUM(B24:C24) -> 15330.559 | F24: 85-89 | G24: 9353.238 | H24: 13038.421 | I24: =SUM(G24:H24) -> 22391.66 | K24: =K18 -> 15/03/2020 | L24: =L18 -> 2020.2078 | M24: =H11 -> 157104.36
A25: Total | B25: =SUM(B7:B24) -> 1692544.8 | C25: =SUM(C7:C24) -> 1713919.6 | D25: =SUM(B25:C25) -> 3406464.4 | F25: Total | G25: =SUM(G7:G24) -> 1853821.8 | H25: =SUM(H7:H24) -> 1888047.3 | I25: =SUM(G25:H25) -> 3741869 | K25: Δt | L25: =L24-L23 -> 9.7582192
K27: 25-29
K28: Fechas | L28: ti | M28: N | N28: r | P28: ti | Q28: Δt | R28: N30/06/2010
A29: Tasas de crecimiento exponencial para el Total de la Población | K29: =K23 -> 40518 | L29: =L23 -> 2010.4495 | M29: =C12 -> 132658.02 | N29: =LN(M30/M29)/L31 -> 0.013108746 | P29: =P23 -> 2019.5 | Q29: =P29-L29 -> 9.0504566 | R29: =M29*EXP($N$29*Q29) -> 149368.24
K30: =K24 -> 15/03/2020 | L30: =L24 -> 2020.2078 | M30: =H12 -> 150760.51
A31: Fechas | B31: ti | C31: N | D31: r | F31: ti | G31: Δt | H31: N30/06/2010 | K31: Δt | L31: =L30-L29 -> 9.7582192
A32: 40518 | B32: 2010.4495 | C32: =D25 -> 3406464.4 | D32: =LN(C33/C32)/B34 -> 0.0096237129 | F32: =2019+6/12+0/365 -> 2019.5 | G32: =F32-B32 -> 9.0504566 | H32: =C32*EXP($D$32*G32) -> 3716468.6
A33: 15/03/2020 | B33: 2020.2078 | C33: =I25 -> 3741869 | K33: 30-34
A34: Δt | B34: =B33-B32 -> 9.7582192 | K34: Fechas | L34: ti | M34: N | N34: r | P34: ti | Q34: Δt | R34: N30/06/2010
K35: =K29 -> 40518 | L35: =L29 -> 2010.4495 | M35: =C13 -> 131127.8 | N35: =LN(M36/M35)/L37 -> 0.0069134349 | P35: =P29 -> 2019.5 | Q35: =P35-L35 -> 9.0504566 | R35: =M35*EXP($N$35*Q35) -> 139594.55
K36: =K30 -> 15/03/2020 | L36: =L30 -> 2020.2078 | M36: =H13 -> 140279.27
K37: Δt | L37: =L36-L35 -> 9.7582192
K39: 35-39
K40: Fechas | L40: ti | M40: N | N40: r | P40: ti | Q40: Δt | R40: N30/06/2010
K41: =K35 -> 40518 | L41: =L35 -> 2010.4495 | M41: =C14 -> 135616.38 | N41: =LN(M42/M41)/L43 -> -0.0017445841 | P41: =P35 -> 2019.5 | Q41: =P41-L41 -> 9.0504566 | R41: =M41*EXP($N$41*Q41) -> 133491.91
K42: =K36 -> 15/03/2020 | L42: =L36 -> 2020.2078 | M42: =H14 -> 133327.18
K43: Δt | L43: =L42-L41 -> 9.7582192
...

Sheet Cuadros a, b, c y d
A1: a. Tasas brutas de natalidad
A2: Tasas brutas de natalidad (b)
A3: Entidad | B3: Bz | C3: N 30-06-z | D3: b
A4: Chihuahua 2019 | B4: ='Chihuahua 2019'!M11 -> 67780 | C4: ='Chihuahua 2019'!H32 -> 3716468.6 | D4: =(B4/C4)*1000 -> 18.237743
A5: Chihuahua 2010 | B5: ='Chihuahua 2010'!M11 -> 65003 | C5: ='Chihuahua 2010'!H32 -> 3408118.9 | D5: =(B5/C5)*1000 -> 19.072985
A7: b. PMEF
A8: Proporción de Mujeres en Edad Fértil
A9: Entidad | B9: MEF 30-06-z | C9: N 30-06-z | D9: PMEF
A10: Chihuahua 2019 | B10: ='Chihuahua 2019'!N11 -> 990018.64 | C10: ='Chihuahua 2019'!H32 -> 3716468.6 | D10: =B10/C10 -> 0.26638692
A11: Chihuahua 2010 | B11: ='Chihuahua 2010'!N11 -> 924662.81 | C11: ='Chihuahua 2010'!H32 -> 3408118.9 | D11: =B11/C11 -> 0.27131178
A13: c. TFG
A14: TFG (3 países)
A15: Entidad | B15: Bz | C15: MEF 30-06-z | D15: TFG | H15: TFG
A16: Chihuahua 2019 | B16: =B4 -> 67780 | C16: =B10 -> 990018.64 | D16: =B16/C16*1000 -> 68.463357 | H16: =D4/D10 -> 68.463357
A17: Chihuahua 2010 | B17: =B5 -> 65003 | C17: =B11 -> 924662.81 | D17: =B17/C17*1000 -> 70.299139 | H17: =D5/D11 -> 70.299139
A19: d. Diferencias relativas de b, TFG, TGF, TBR y TNR de Brasil con respecto a Panamá
A21: Entidad | B21: Δ
B22: b | C22: TFG | D22: TGF | E22: TBR | F22: TNR
A23: Chihuahua 2010-Chihuahua 2019 | B23: =(D5/D4-1)*100 -> 4.5797417 | C23: =(D17/D16-1)*100 -> 2.6814082 | D23: =('TGF, TBR y TNR'!G12/'TGF, TBR y TNR'!G27-1)*100 -> 0.95855722 | E23: =('[1]TGF, TBR y TNR'!I13/'[1]TGF, TBR y TNR'!I28-1)*100 -> -35.146227 | F23: =('[1]TGF, TBR y TNR'!L14/'[1]TGF, TBR y TNR'!L29-1)*100 -> -35.278779

Sheet TGF, TBR y TNR
A1: Brasil | I1: K
I2: =100/205 -> 0.48780488 | N2: =G27-G12 -> -0.021608033
A3: Edad | B3: Punto medio | C3: x | D3: x+n | E3: Nacimientos | F3: Población femenina 30/06/2010 | G3: f(x,5) | H3: % f(x,5) | I3: f(x,5) fem | J3: L(x) fem | K3: m+2,5P0 | L3: m+2,5P0 * f(x,5)fem
A4: 15-19 | B4: 17.5 | C4: 15 | D4: 19 | E4: ='Chihuahua 2010'!M4 -> 14662 | F4: ='Chihuahua 2010'!N4 -> 164495.41 | G4: =E4/F4 -> 0.089133184 | H4: =G4/$G$11 -> 0.19582543 | I4: =G4*$I$2 -> 0.043479602 | J4: 489434.45 | K4: =J4/(5*100000) -> 0.9788689 | L4: =K4*I4 -> 0.04256083
A5: 20-24 | B5: 22.5 | C5: 20 | D5: 24 | E5: ='Chihuahua 2010'!M5 -> 19720 | F5: ='Chihuahua 2010'!N5 -> 147419.16 | G5: =E5/F5 -> 0.13376823 | H5: =G5/$G$11 -> 0.29388854 | I5: =G5*$I$2 -> 0.065252795 | J5: 486299.17 | K5: =J5/(5*100000) -> 0.97259833 | L5: =K5*I5 -> 0.06346476
A6: 25-29 | B6: 27.5 | C6: 25 | D6: 29 | E6: ='Chihuahua 2010'!M6 -> 15058 | F6: ='Chihuahua 2010'!N6 -> 132745.79 | G6: =E6/F6 -> 0.11343486 | H6: =G6/$G$11 -> 0.24921617 | I6: =G6*$I$2 -> 0.055334078 | J6: 482737.42 | K6: =J6/(5*100000) -> 0.96547484 | L6: =K6*I6 -> 0.05342366
A7: 30-34 | B7: 32.5 | C7: 30 | D7: 34 | E7: ='Chihuahua 2010'!M7 -> 9635 | F7: ='Chihuahua 2010'!N7 -> 131173.54 | G7: =E7/F7 -> 0.073452311 | H7: =G7/$G$11 -> 0.16137458 | I7: =G7*$I$2 -> 0.035830396 | J7: 478720.44 | K7: =J7/(5*100000) -> 0.95744087 | L7: =K7*I7 -> 0.034305485
A8: 35-39 | B8: 37.5 | C8: 35 | D8: 39 | E8: ='Chihuahua 2010'!M8 -> 4748 | F8: ='Chihuahua 2010'!N8 -> 135604.44 | G8: =E8/F8 -> 0.035013603 | H8: =G8/$G$11 -> 0.076924817 | I8: =G8*$I$2 -> 0.017079806 | J8: 474615.59 | K8: =J8/(5*100000) -> 0.94923119 | L8: =K8*I8 -> 0.016212685
A9: 40-44 | B9: 42.5 | C9: 40 | D9: 44 | E9: ='Chihuahua 2010'!M9 -> 1050 | F9: ='Chihuahua 2010'!N9 -> 116382.7 | G9: =E9/F9 -> 0.0090219594 | H9: =G9/$G$11 -> 0.019821227 | I9: =G9*$I$2 -> 0.0044009558 | J9: 470037.83 | K9: =J9/(5*100000) -> 0.94007565 | L9: =K9*I9 -> 0.0041372314
A10: 45-49 | B10: 47.5 | C10: 45 | D10: 49 | E10: ='Chihuahua 2010'!M10 -> 130 | F10: ='Chihuahua 2010'!N10 -> 96841.767 | G10: =E10/F10 -> 0.001342396 | H10: =G10/$G$11 -> 0.0029492414 | I10: =G10*$I$2 -> 0.00065482731 | J10: 463489.96 | K10: =J10/(5*100000) -> 0.92697992 | L10: =K10*I10 -> 0.00060701177
A11: Total | G11: =SUM(G4:G10) -> 0.45516654 | L11: =SUM(L4:L10) -> 0.21471166
F12: TGF | G12: =SUM(G4:G10)*5 -> 2.2758327
F13: TBR | I13: =G12*I2 -> 1.1101623 | K13: TBR (K obs) | L13: =G12*'Chihuahua 2010'!Q8 -> 1.1179875
F14: TNR | L14: =L11*5 -> 1.0735583
A16: Panamá
A18: Edad | B18: Punto medio | C18: x | D18: x+n | E18: Nacimientos | F18: Población femenina 30/06/2009 | G18: f(x,5) | H18: % f(x,5) | I18: f(x,5) fem | J18: L(x) fem | K18: m+2,5P0 | L18: m+2,5P0 * f(x,5)fem
A19: 15-19 | B19: 17.5 | C19: 15 | D19: 19 | E19: ='Chihuahua 2019'!M4 -> 13227 | F19: ='Chihuahua 2019'!N4 -> 160989.22 | G19: =E19/F19 -> 0.082160781 | H19: =G19/$G$26 -> 0.18223734 | I19: =G19*$I$2 -> 0.04007843 | J19: 488781.66 | K19: =J19/(5*100000) -> 0.97756332 | L19: =K19*I19 -> 0.039179203
A20: 20-24 | B20: 22.5 | C20: 20 | D20: 24 | E20: ='Chihuahua 2019'!M5 -> 20308 | F20: ='Chihuahua 2019'!N5 -> 156377.23 | G20: =E20/F20 -> 0.12986546 | H20: =G20/$G$26 -> 0.28804905 | I20: =G20*$I$2 -> 0.063349003 | J20: 486372.91 | K20: =J20/(5*100000) -> 0.97274581 | L20: =K20*I20 -> 0.061622477 | O20: Panamá | P20: Brasil
A21: 25-29 | B21: 27.5 | C21: 25 | D21: 29 | E21: ='Chihuahua 2019'!M6 -> 18618 | F21: ='Chihuahua 2019'!N6 -> 149368.24 | G21: =E21/F21 -> 0.12464497 | H21: =G21/$G$26 -> 0.27646972 | I21: =G21*$I$2 -> 0.060802426 | J21: 483709.69 | K21: =J21/(5*100000) -> 0.96741938 | L21: =K21*I21 -> 0.058821445 | N21: =F28 -> TBR | O21: =I28 -> 1.0996218 | P21: =I13 -> 1.1101623
A22: 30-34 | B22: 32.5 | C22: 30 | D22: 34 | E22: ='Chihuahua 2019'!M7 -> 10132 | F22: ='Chihuahua 2019'!N7 -> 139594.55 | G22: =E22/F22 -> 0.072581632 | H22: =G22/$G$26 -> 0.16099023 | I22: =G22*$I$2 -> 0.035405674 | J22: 480957.63 | K22: =J22/(5*100000) -> 0.96191526 | L22: =K22*I22 -> 0.034057258 | N22: =F29 -> TNR | O22: =L29 -> 1.0650937 | P22: =L14 -> 1.0735583
A23: 35-39 | B23: 37.5 | C23: 35 | D23: 39 | E23: ='Chihuahua 2019'!M8 -> 4453 | F23: ='Chihuahua 2019'!N8 -> 133491.91 | G23: =E23/F23 -> 0.033357828 | H23: =G23/$G$26 -> 0.07398958 | I23: =G23*$I$2 -> 0.016272111 | J23: 477650.93 | K23: =J23/(5*100000) -> 0.95530187 | L23: =K23*I23 -> 0.015544778 | N23: diff | O23: =O21-O22 -> 0.034528091 | P23: =P21-P22 -> 0.036603984
A24: 40-44 | B24: 42.5 | C24: 40 | D24: 44 | E24: ='Chihuahua 2019'!M9 -> 918 | F24: ='Chihuahua 2019'!N9 -> 127012.18 | G24: =E24/F24 -> 0.0072276531 | H24: =G24/$G$26 -> 0.01603135 | I24: =G24*$I$2 -> 0.0035256844 | J24: 472986.94 | K24: =J24/(5*100000) -> 0.94597389 | L24: =K24*I24 -> 0.0033352054
A25: 45-49 | B25: 47.5 | C25: 45 | D25: 49 | E25: ='Chihuahua 2019'!M10 -> 124 | F25: ='Chihuahua 2019'!N10 -> 123185.32 | G25: =E25/F25 -> 0.0010066134 | H25: =G25/$G$26 -> 0.0022327265 | I25: =G25*$I$2 -> 0.00049103095 | J25: 466746.66 | K25: =J25/(5*100000) -> 0.93349332 | L25: =K25*I25 -> 0.00045837411
A26: Total | G26: =SUM(G19:G25) -> 0.45084494 | L26: =SUM(L19:L25) -> 0.21301874
F27: TGF | G27: =SUM(G19:G25)*5 -> 2.2542247
F28: TBR | I28: =G27*I2 -> 1.0996218 | K28: TBR (K obs) | L28: =G27*'Chihuahua 2019'!Q8 -> 1.1066084
F29: TNR | L29: =L26*5 -> 1.0650937

Sheet Hoja1
